Workbook
Name list1: #REF!
Name list1: #REF!
Name list1: #REF!
Name list1: #REF!
Name list1: #REF!
Name list2: #REF!
Name list2: #REF!
Name list2: #REF!
Name list2: #REF!
Name list2: #REF!
Name list3: #REF!
Name list3: #REF!
Name list3: #REF!
Name list3: #REF!
Name list3: #REF!
Name list4: #REF!
Name list4: #REF!
Name list4: #REF!
Name list4: #REF!
Name list4: #REF!
Name list5: #REF!
Name list5: #REF!
Name list5: #REF!
Name list5: #REF!
Name list5: #REF!
Name list6: #REF!
Name list6: #REF!
Name list6: #REF!
Name list6: #REF!
Name list6: #REF!
Name list7: #REF!
Name list7: #REF!
Name list7: #REF!
Name list7: #REF!
Name list7: #REF!

Sheet Start
A2: Tư vấn tài chính | B2: Mã số tư vấn viên | C2: Số điện thoại | D2: Email
A3: Phạm Quang Hà | B3: 101012337 | C3: 0981984554 | D3: quangha1659@gmail.com
A4: Xác nhận Quyền sử dụng file: | C4: =IF(AND(A3="Phạm Quang Hà",B3="101012337"),"OK!","Đang dùng lậu, hãy mua file!") -> OK!
A5: Hãy làm việc chuyên nghiệp & tận tâm nhé! | C5: Video HDSD: | D5: https://youtu.be/Vc3PZKKPQNQ
A25: Bản quyền @Huy Trần MDRT | M: 09 8118 8866 | Email: huytranibo@gmail.com | www.huytranmdrt.com

Sheet Gioithieubanthan
R5: Link Canva ACE có thể sửa tại đây:
R7: https://www.canva.com/design/DAG2AGJB90c/cYj0FXOAxcazeTw6XLGZJA/view?utm_content=DAG2AGJB90c&utm_campaign=designshare&utm_medium=link&utm_source=publishsharelink&mode=preview
R11: Sau khi sửa xong lưu ảnh, xóa ảnh của Huy và copy paste ảnh của ACE vào, xóa tất cả những dòng bên này, lưu ảnh lại tại 1 folder sau này nhận các bản cập nhật thì copy paste ảnh lại.

Sheet Hoach dinh tai chinh
B2: KHẢO SÁT ƯU TIÊN TÀI CHÍNH HIỆN NAY
B3: Ngày chạy bảng minh họa (đang mặc định là hiện tại, có thể thay đổi để xem lại GTTK BMH cũ): | J3: =TODAY() -> 46229
B4: Họ và tên (gõ từng chữ không dấu vào từng ô): | D4: TRAN | E4: VAN | F4: HUY
B5: Ngày tháng năm sinh theo CCCD (tặng báo cáo thần số học): | J5: 34926
B6: Số điện thoại (Kết bạn Zalo gửi files): | J6: 0981188866
B7: Tuổi: | J7: =DATEDIF(J5,J3,"y") -> 30
B8: Chọn giới tính: | J8: Nam
B9: Nhu cầu tài chính nào quan trọng với anh chị hiện nay?
B10: Bảo vệ tài chính chu cấp cho người thân
B11: Tích lũy Quỹ học đại học cho con
B12: Tích lũy Quỹ hưu trí cho tương lai
B13: Đầu tư gia tăng tài sản
B14: Quỹ chăm sóc sức khỏe

Sheet Chitieu
B1: QUY TẮC 50/30/20 TRONG TÀI CHÍNH CÁ NHÂN của Elizabeth Warren & Amelia Warren Tyagi
B2: 50: Chi tối đa 50% thu nhập ròng cho các nhu cầu thiết yếu | F2: 30: Chi tối đa 30% thu nhập ròng cho các nhu cầu không thiết yếu | J2: 20: Dành tối thiểu 20% thu nhập ròng cho đầu tư và/hoặc trả nợ
B4: THU NHẬP RÒNG BÌNH QUÂN/THÁNG | D4: 70000000
B5: A. NHU CẦU THIẾT YẾU | F5: B. CÁC CHI PHÍ KHÁC (KHÔNG THIẾT YẾU) | J5: C. TIẾT KIỆM(ĐẦU TƯ)/ TRẢ NỢ | M5: =IF(D23+H13+L11>100%,"Đang chi tiêu nhiều hơn số kiếm ra kìa!, hãy kiểm tra lại!","Ô thế tiền đi đâu nhỉ? Sao tổng chi lại nhỏ hơn tổng thu?, hãy kiểm tra lại!") -> Ô thế tiền đi đâu nhỉ? Sao tổng chi lại nhỏ hơn tổng thu?, hãy kiểm tra lại!
B6: STT | C6: MỤC | D6: SỐ TIỀN/THÁNG | F6: STT | G6: MỤC | H6: SỐ TIỀN/THÁNG | J6: STT | K6: MỤC | L6: SỐ TIỀN/THÁNG
B7: 1 | C7: Thuê nhà/ Trả góp nhà | D7: 0 | F7: 1 | G7: Giao tế xã hội (ma chay hiếu hỉ) | H7: 5000000 | J7: 1 | K7: Trả nợ | L7: 2000000
B8: 2 | C8: Gas | F8: 2 | G8: Du lịch | H8: 2000000 | J8: 2 | K8: Tiết kiệm/đầu tư | L8: 3000000
B9: 3 | C9: Nước | F9: 3 | G9: Quần áo xa xỉ | H9: 3000000 | J9: 3 | K9: Khác
B10: 4 | C10: Điện | F10: 4 | G10: Các loại thuê bao (TV, Internet, Netflix…) | H10: 500000 | J10: TỔNG CỘNG | L10: =SUM(L7:L9) -> 5000000
B11: 5 | C11: Xăng dầu | F11: 5 | G11: Khác | J11: % TIẾT KIỆM(ĐẦU TƯ) HOẶC TRẢ NỢ/ THU NHẬP RÒNG | L11: =L10/D4 -> 0.071428571
B12: 6 | C12: Thuê bao điện thoại | F12: TỔNG CỘNG | H12: =SUM(H7:H11) -> 10500000
B13: 7 | C13: Bảo hiểm xe hơi | F13: % NHU CẦU KHÔNG THIẾT YẾU/ THU NHẬP RÒNG | H13: =H12/D4 -> 0.15
B14: 8 | C14: Bảo hiểm y tế
B15: 9 | C15: Bảo hiểm nhân thọ
B16: 10 | C16: Nhu yếu phẩm cần thiết | F16: TỔNG HỢP
B17: 11 | C17: Quần áo cần thiết
B18: 12 | C18: Giáo dục | F18: Nhu cầu | H18: Quy tắc | I18: Bạn đang phân bổ | M18: Nhận xét chung
B19: 13 | C19: Y tế
B20: 14 | C20: Phụng dưỡng cha mẹ | F20: Nhu cầu thiết yếu | H20: 0.5 | I20: =D23 -> 0 | M20: =IF(I20<=50%,"Bạn thật tuyệt!","Hãy rà soát lại chi tiêu xem có thể giảm chi phí cho mục nào không") -> Bạn thật tuyệt!
B21: 15 | C21: Khác (chỉ những chi phí bắt buộc) | D21: 0
B22: TỔNG CỘNG | D22: =IF((SUM(D7:D21)>D4),"Hãy tính lại!",(SUM(D7:D21))) -> 0 | F22: Nhu cầu không thiết yếu | H22: 0.3 | I22: =H13 -> 0.15 | M22: =IF(I22<=30%,"Bạn đang đi đúng hướng. Nhưng cũng đừng quá keo kiệt nhé. Hãy cho người thân hưởng nhiều hương vị cuộc đời nữa","Xa xỉ quá bạn ơi! Đừng bị hào nhoáng và cám dỗ làm khổ tương lai bạn") -> Bạn đang đi đúng hướng. Nhưng cũng đừng quá keo kiệt nhé. Hãy cho người thân hưởng nhiều hương vị cuộc đời nữa
B23: % NHU CẦU THIẾT YẾU/ THU NHẬP RÒNG | D23: =D22/D4 -> 0
B24: THU NHẬP KHẢ DỤNG | D24: =D4-D22 -> 70000000 | F24: Trả nợ/ tiết kiệm/ đầu tư | H24: 0.2 | I24: =L11 -> 0.071428571 | M24: =IF(I24<20%,"Coi chừng túng quẫn! Lúc không có tiền thật là bi ai!","Bạn biết nhìn xa trông rộng vì tương lai bản thân và gia đình.") -> Coi chừng túng quẫn! Lúc không có tiền thật là bi ai!
B25: DỰ ĐỊNH CHO MỤC TIÊU ƯU TIÊN MỖI THÁNG
B26: DỰ ĐỊNH CHO MỤC TIÊU ƯU TIÊN MỖI NĂM | D26: =D25*12 -> 0

Sheet Tinh phi QL
B1: CHU Ý! CHỈ NHẬP/ CHỌN THÔNG TIN Ô MÀU VÀNG
B2: Tư vấn tài chính: | C2: =Start!A3 -> Phạm Quang Hà | E2: Mã số tư vấn viên: | F2: =Start!B3 -> 101012337 | G2: Quyền sử dụng: | H2: =Start!C4 -> OK! | J2: Bản quyền thuộc về Huy Trần MDRT Liên hệ mua file: 09 8118 8866
B3: Tổng phí đóng năm đầu tiên dành cho cả gia đình | H3: =IFERROR(H26,0)+IFERROR(H65,0)+IFERROR(H84,0)+IFERROR(SUM(H33:I44),0)+IFERROR(H45,0) -> 16571000
B4: Tiết kiệm theo tháng | E4: =ROUND(H3/12,-3) -> 1381000 | F4: Tiết kiệm theo ngày | H4: =ROUND(H3/365,-3) -> 45000 | J4: =IF(H2="Đang dùng lậu!","Vui lòng không dùng lậu. Hãy mua và sử dụng để tôn trọng tác giả và chính mình",0) -> 0
A5: 2024 | B5: Bảng Tính Biểu Phí UL & SP đính kèm
B6: PHẦN 1. NGƯỜI ĐƯỢC BẢO HIỂM CHÍNH
B7: Họ và tên: | F7: =CONCATENATE('Hoach dinh tai chinh'!D4," ",'Hoach dinh tai chinh'!E4," ",'Hoach dinh tai chinh'!F4," ",'Hoach dinh tai chinh'!G4," ",'Hoach dinh tai chinh'!H4," ",'Hoach dinh tai chinh'!I4," ",'Hoach dinh tai chinh'!J4) -> TRAN VAN HUY
B8: Ngày tháng năm sinh: | F8: ='Hoach dinh tai chinh'!J5 -> 34926 | H8: Tuổi | I8: =DATEDIF(F8,NOW(),"y") -> 30
B9: Giới tính: | H9: ='Hoach dinh tai chinh'!J8 -> Nam
B10: Chọn loại nghề nghiệp: | H10: Loại: | I10: 2
B11: Tên Quyền lợi (Chọn 1 SPC) | D11: Chọn Thời hạn DP | E11: B1. Nhập STBH | F11: Số phí Min | G11: Số phí Max | H11: Số phí BH
B12: Khỏe Trọn Vẹn - Bền Vững | D12: 15 | E12: 0 | H12: =E12/1000*IF(B12=0,0,IF(B12=KTV!D1,INDEX(KTV!D3:E73,MATCH('Tinh phi QL'!I8,KTV!A3:A73,0),MATCH('Tinh phi QL'!H9,KTV!D2:E2,0)),IF(B12=KTV!F1,INDEX(KTV!F3:G73,MATCH('Tinh phi QL'!I8,KTV!A3:A73,),MATCH('Tinh phi QL'!H9,KTV!F2:G2,0)),IF(B12=KTV!B1,INDEX(KTV!B3:C73,MATCH('Tinh phi QL'!I8,KTV!A3:A73,0),MATCH('Tinh phi QL'!H9,KTV!B2:C2,0)),IF(B12=KTV!H1,INDEX(KTV!H3:I73,MATCH('Tinh phi QL'!I8,KTV!A3:A73,0),MATCH('Tinh phi QL'!H9,KTV!H2:I2,0))))))) -> 0 | J12: =IF(AND(B12="Khỏe trọn vẹn - tối ưu",D12>1),"Khỏe trọn vẹn tối ưu chỉ đóng phí 1 năm, hãy xem lại!",IF(AND(OR(E12<>0,H12<>0),H13<>0),"Chỉ chọn 1 SP chính, hãy xem lại xóa STBH 1 SPC",IF(AND(E12<>0,E12<2000000000,H12<30000000),"STBH min 2 tỷ hoặc phí SPC min 30 triệu, hãy xem lại!",0))) -> 0
B13: Khỏe Bình An | D13: 20 | E13: 1000000000 | F13: =IF(OR(B13="Khỏe Bình An",B13="Vững Tương Lai"),E13/VLOOKUP(I8,KBA!A1:C67,3,0),0) -> 8333333.3 | G13: =IF(OR(B13="Khỏe Bình An",B13="Vững Tương Lai"),E13/VLOOKUP(I8,KBA!A1:C67,2,0),0) -> 40000000 | H13: 10000000 | J13: =IF(B13=0,0,IF(AND(H12=0,OR(H13=0,G13=0)),"Chưa có số phí hoặc STBH, Khỏe Bình An hay Vững Tương Lai hãy nhập STBH trước!",IF(AND(H13<>0,OR(H13<F13,H13>G13)),"Nhập số phí trong dải Min,Max, hãy xem lại!"," ")))
B14: Bảo hiểm Tử vong và thương tật do tai nạn | G14: 500000000 | H14: =IF(I10=1,G14*3.37/1000,IF(I10=2,G14*4.54/1000,IF(I10=3,G14*8.37/1000,IF(I10=4,G14*12.16/1000,0)))) -> 2270000
B15: Bảo hiểm Hỗ trợ chi phí nằm viện | G15: 0 | H15: =IF(G15=0,0,IF(I8=0,0,VLOOKUP(I8,TCYT!A2:B60,2,0)*'Tinh phi QL'!G15/100)) -> 0 | J15: =IF(AND(G15<>0,I8=0),"Không bán cho 0T, hãy xem lại!"," ")
B16: Bảo hiểm Toàn diện Bệnh hiểm nghèo 2.0 | E16: Thời hạn BH max (năm) | F16: =85-I8 -> 55 | G16: 300000000 | H16: =G16/1000*IF(H9="Nam",VLOOKUP(I8,BHN!$A$2:$C$87,2,0),IF(H9="Nữ",VLOOKUP(I8,BHN!$A$2:$C$87,3,0))) -> 606000 | K16: =IF(G17="Cơ bản",1,IF(G17="nâng cao",2,IF(G17="toàn diện",3,IF(G17="hoàn hảo",4,0)))) -> 2
B17: Bảo hiểm chăm sóc sức khỏe Trọn đời - Nội Trú (Chọn phạm vi bảo lãnh) | F17: Việt Nam | G17: Nâng cao | H17: =IF(G17=0,0,IF(AND(G17<>0,F17="Việt Nam"),INDEX(TTD!$B$3:$E$102,MATCH('Tinh phi QL'!I8,TTD!$A$3:$A$102,0),MATCH('Tinh phi QL'!G17,TTD!$B$2:$E$2,0)),IF(AND(G17<>0,F17="Toàn cầu"),INDEX(TTD!$F$3:$I$102,MATCH('Tinh phi QL'!I8,TTD!$A$3:$A$102,0),MATCH('Tinh phi QL'!G17,TTD!$F$2:$I$2,0))))) -> 3695000 | J17: =IF(AND(MAX($H$13,H12)<10000000,OR(G17="Toàn diện",G17="hoàn hảo")),"Thẻ toàn diện/ hoàn hảo phí SPC tối thiểu 10 triệu, hãy xem lại!"," ") | K17: =IF(G18="Cơ bản",1,IF(G18="nâng cao",2,IF(G18="toàn diện",3,IF(G18="hoàn hảo",4,0)))) -> 0
B18: Hạn mức năm: Cơ bản: 150 triệu, Nâng cao: 350 triệu, Toàn diện: 700 triệu, Hoàn hảo: 1.2 tỷ | K18: =IF(G19="Cơ bản",1,IF(G19="nâng cao",2,IF(G19="toàn diện",3,IF(G19="hoàn hảo",4,0)))) -> 0
B19: Bảo hiểm chăm sóc sức khỏe Trọn đời - Ngoại Trú | G19: 0 | H19: =IF(G19=0,0,INDEX(TTD!$J$3:$M$102,MATCH('Tinh phi QL'!I8,TTD!$A$3:$A$102,0),MATCH('Tinh phi QL'!G19,TTD!$J$2:$M$2,0))) -> 0 | J19: =IF(K18>K16,"Thẻ ngoại trú ko dc cao hơn nội trú, hãy xem lại!", " ") | K19: =IF(G20="Cơ bản",1,IF(G20="nâng cao",2,IF(G20="toàn diện",3,IF(G20="hoàn hảo",4,0)))) -> 0
B20: Hạn mức năm: Cơ bản: 6 triệu, Nâng cao: 12 triệu, Toàn diện: 24 triệu, Hoàn hảo: 48 triệu | K20: =IF(G21="Cơ bản",1,IF(G21="nâng cao",2,IF(G21="toàn diện",3,IF(G21="hoàn hảo",4,0)))) -> 0
B21: Bảo hiểm chăm sóc sức khỏe Trọn đời - Nha khoa | G21: 0 | H21: =IF(G21=0,0,INDEX(TTD!$N$3:$Q$102,MATCH('Tinh phi QL'!I8,TTD!$A$3:$A$102,0),MATCH('Tinh phi QL'!G21,TTD!$N$2:$Q$2,0))) -> 0 | J21: =IF(K20>K16,"Thẻ nha khoa ko dc cao hơn nội trú, hãy xem lại!", " ") | K21: =IF(G22="Cơ bản",1,IF(G22="nâng cao",2,IF(G22="toàn diện",3,IF(G22="hoàn hảo",4,0)))) -> 0
B22: Hạn mức năm: Cơ bản: 1 triệu, Nâng cao: 2 triệu, Toàn diện: 5 triệu, Hoàn hảo: 10 triệu | K22: =IF(G23="Cơ bản",1,IF(G23="nâng cao",2,IF(G23="toàn diện",3,IF(G23="hoàn hảo",4,0)))) -> 0
B23: Bảo hiểm chăm sóc sức khỏe trọn đời - Thai sản | G23: =IF(OR(G17="Cơ Bản",G17="Nâng cao"),0,G17) -> 0 | K23: =IF(G24="Cơ bản",1,IF(G24="nâng cao",2,IF(G24="toàn diện",3,IF(G24="hoàn hảo",4,0)))) -> 0
B24: Toàn diện: 25 triệu, Hoàn hảo: 25 triệu, Năm 1: 50%, Năm 2: 80%, Năm 3: 100% | K24: =IF(G25="Cơ bản",1,IF(G25="nâng cao",2,IF(G25="toàn diện",3,IF(G25="hoàn hảo",4,0)))) -> 0
B25: Bảo hiểm tử kỳ gia hạn hàng năm | G25: 0 | H25: ='Tinh phi QL'!G25/1000*IF(H9="Nam",VLOOKUP(I8,Tuky!$A$2:$C$86,2,0),IF(H9="Nữ",VLOOKUP(I8,Tuky!$A$2:$C$86,3,0),0)) -> 0 | K25: =IF(G26="Cơ bản",1,IF(G26="nâng cao",2,IF(G26="toàn diện",3,IF(G26="hoàn hảo",4,0)))) -> 0
B26: Tổng phí đóng năm đầu tiên dành cho NĐBH chính | H26: =IF(H2="OK!",_xlfn.AGGREGATE(9,6,H12:I25),"Đang dùng lậu!") -> 16571000 | K26: =IF(G27="Cơ bản",1,IF(G27="nâng cao",2,IF(G27="toàn diện",3,IF(G27="hoàn hảo",4,0)))) -> 0
B27: PHẦN 2. NGƯỜI ĐƯỢC BẢO HIỂM ĐÍNH KÈM - 2.1. NĐBH ĐÍNH KÈM 1 | K27: =IF(G28="Cơ bản",1,IF(G28="nâng cao",2,IF(G28="toàn diện",3,IF(G28="hoàn hảo",4,0)))) -> 0
B28: Nhập họ và tên: | F28: Đỗ Thị X | K28: =IF(G29="Cơ bản",1,IF(G29="nâng cao",2,IF(G29="toàn diện",3,IF(G29="hoàn hảo",4,0)))) -> 0
B29: Nhập ngày tháng năm sinh: | F29: 45866 | H29: Tuổi | I29: =DATEDIF(F29,NOW(),"y") -> 0 | K29: =IF(G30="Cơ bản",1,IF(G30="nâng cao",2,IF(G30="toàn diện",3,IF(G30="hoàn hảo",4,0)))) -> 0
B30: Chọn giới tính: | H30: Nữ | K30: =IF(G31="Cơ bản",1,IF(G31="nâng cao",2,IF(G31="toàn diện",3,IF(G31="hoàn hảo",4,0)))) -> 0
B31: Chọn loại nghề nghiệp: | H31: Loại: | I31: 1 | K31: =IF(G32="Cơ bản",1,IF(G32="nâng cao",2,IF(G32="toàn diện",3,IF(G32="hoàn hảo",4,0)))) -> 0
B32: Tên Quyền lợi | F32: Số tiền bảo hiểm (đ) | H32: Phí đóng (đ) | K32: =IF(G33="Cơ bản",1,IF(G33="nâng cao",2,IF(G33="toàn diện",3,IF(G33="hoàn hảo",4,0)))) -> 0
B33: Bảo hiểm Tử vong và thương tật do tai nạn | H33: =IF(I31=1,G33*3.37/1000,IF(I31=2,G33*4.54/1000,IF(I31=3,G33*8.37/1000,IF(I31=4,G33*12.16/1000,0)))) -> 0 | K33: =IF(G34="Cơ bản",1,IF(G34="nâng cao",2,IF(G34="toàn diện",3,IF(G34="hoàn hảo",4,0)))) -> 0
B34: Bảo hiểm Hỗ trợ chi phí nằm viện | H34: =IF(G34=0,0,IF(I29=0,0,VLOOKUP(I29,TCYT!A2:B60,2,0)*'Tinh phi QL'!G34/100)) -> 0 | J34: =IF(AND(G34<>0,I29=0),"Không bán cho 0T, hãy xem lại!"," ") | K34: =IF(G35="Cơ bản",1,IF(G35="nâng cao",2,IF(G35="toàn diện",3,IF(G35="hoàn hảo",4,0)))) -> 0
B35: Bảo hiểm Toàn diện Bệnh hiểm nghèo 2.0 | E35: Thời hạn BH max (năm) | F35: =85-I28 -> 85 | H35: =G35/1000*IF(H30="Nam",VLOOKUP(I29,BHN!$A$2:$C$87,2,0),IF(H30="Nữ",VLOOKUP(I29,BHN!$A$2:$C$87,3,0))) -> 0 | K35: =IF(G36="Cơ bản",1,IF(G36="nâng cao",2,IF(G36="toàn diện",3,IF(G36="hoàn hảo",4,0)))) -> 0
B36: Bảo hiểm chăm sóc sức khỏe Trọn đời - Nội Trú (Chọn phạm vi bảo lãnh) | F36: Việt Nam | G36: 0 | H36: =IF(G36=0,0,IF(AND(G36<>0,F36="Việt Nam"),INDEX(TTD!$B$3:$E$102,MATCH('Tinh phi QL'!I29,TTD!$A$3:$A$102,0),MATCH('Tinh phi QL'!G36,TTD!$B$2:$E$2,0)),IF(AND(G36<>0,F36="Toàn cầu"),INDEX(TTD!$F$3:$I$102,MATCH('Tinh phi QL'!I29,TTD!$A$3:$A$102,0),MATCH('Tinh phi QL'!G36,TTD!$F$2:$I$2,0))))) -> 0 | J36: =IF(AND(MAX($H$13,H12)<10000000,OR(G36="Toàn diện",G36="hoàn hảo")),"Thẻ toàn diện/ hoàn hảo phí SPC tối thiểu 10 triệu, hãy xem lại!"," ") | K36: =IF(G37="Cơ bản",1,IF(G37="nâng cao",2,IF(G37="toàn diện",3,IF(G37="hoàn hảo",4,0)))) -> 0
B37: Hạn mức năm: Cơ bản: 150 triệu, Nâng cao: 350 triệu, Toàn diện: 700 triệu, Hoàn hảo: 1.2 tỷ | K37: =IF(G38="Cơ bản",1,IF(G38="nâng cao",2,IF(G38="toàn diện",3,IF(G38="hoàn hảo",4,0)))) -> 0
B38: Bảo hiểm chăm sóc sức khỏe Trọn đời - Ngoại Trú | H38: =IF(G38=0,0,INDEX(TTD!$J$3:$M$102,MATCH('Tinh phi QL'!I29,TTD!$A$3:$A$102,0),MATCH('Tinh phi QL'!G38,TTD!$J$2:$M$2,0))) -> 0 | J38: =IF(K37>K35,"Thẻ ngoại trú ko dc cao hơn nội trú, hãy xem lại!", " ") | K38: =IF(G39="Cơ bản",1,IF(G39="nâng cao",2,IF(G39="toàn diện",3,IF(G39="hoàn hảo",4,0)))) -> 0
B39: Hạn mức năm: Cơ bản: 6 triệu, Nâng cao: 12 triệu, Toàn diện: 24 triệu, Hoàn hảo: 48 triệu | K39: =IF(G40="Cơ bản",1,IF(G40="nâng cao",2,IF(G40="toàn diện",3,IF(G40="hoàn hảo",4,0)))) -> 0
B40: Bảo hiểm chăm sóc sức khỏe Trọn đời - Nha khoa | H40: =IF(G40=0,0,INDEX(TTD!$N$3:$Q$102,MATCH('Tinh phi QL'!I29,TTD!$A$3:$A$102,0),MATCH('Tinh phi QL'!G40,TTD!$N$2:$Q$2,0))) -> 0 | J40: =IF(K39>K35,"Thẻ nha khoa ko dc cao hơn nội trú, hãy xem lại!", " ") | K40: =IF(G41="Cơ bản",1,IF(G41="nâng cao",2,IF(G41="toàn diện",3,IF(G41="hoàn hảo",4,0)))) -> 0
...

Sheet Hoavon
B1: NĂM HÒA VỐN - VỊ TRÍ GIAO CẮT GIỮA ĐƯỜNG PHÍ SẢN PHẨM CHÍNH & ĐƯỜNG GIÁ TRỊ HOÀN LẠI
B2: Năm HĐ | C2: Năm đóng phí dự kiến | D2: Số phí sản phẩm chính lũy kế | E2: Giá trị hoàn lại LS cam kết | F2: Giá trị hoàn lại LS minh họa
B3: 1 | C3: =IF(AND('Tinh phi QL'!$H$13=0,'Tinh phi QL'!$H$12<>0),IF(ROW(A1)>'Tinh phi QL'!$D$12,"",ROW(A1)),IF(ROW(A1)>'Tinh phi QL'!$D$12,"",ROW(A1))) -> 1 | D3: =IF(IFERROR(--TRIM(C3),0)=0,0,IF(AND('Tinh phi QL'!$H$13=0,'Tinh phi QL'!$H$12<>0),'Tinh phi QL'!$H$12/1000,'Tinh phi QL'!$H$13/1000)) -> 10000 | E3: =IF(AND('Tinh phi QL'!$B$12="Khỏe trọn vẹn - Tối ưu",'Tinh phi QL'!$E$13=0),KTVTUGTTKcamket!M7,IF(AND('Tinh phi QL'!$B$12="Khỏe trọn vẹn - bền vững",'Tinh phi QL'!$E$13=0),KTVBVGTTKcamket!M7,IF(AND('Tinh phi QL'!$B$12="Khỏe trọn vẹn - trọn đời",'Tinh phi QL'!$E$13=0),KTVTRDGTTKcamket!M7,IF(AND('Tinh phi QL'!$B$12="Khỏe trọn vẹn - toàn diện",'Tinh phi QL'!$E$13=0),KTVTDGTTKcamket!M7,IF(AND('Tinh phi QL'!$H$12=0,'Tinh phi QL'!$B$13="Khỏe Bình An"),KBAGTTKcamket!M7,IF(AND('Tinh phi QL'!$H$12=0,'Tinh phi QL'!$B$13="Vững Tương Lai"),VTLGTTKcamket!M7,0)))))) -> 0 | F3: =IF(AND('Tinh phi QL'!$B$12="Khỏe trọn vẹn - Tối ưu",'Tinh phi QL'!$E$13=0),KTVTUGTTKMH!M7,IF(AND('Tinh phi QL'!$B$12="Khỏe trọn vẹn - bền vững",'Tinh phi QL'!$E$13=0),KTVBVGTTKMH!M7,IF(AND('Tinh phi QL'!$B$12="Khỏe trọn vẹn - trọn đời",'Tinh phi QL'!$E$13=0),KTVTRDGTTKMH!M7,IF(AND('Tinh phi QL'!$B$12="Khỏe trọn vẹn - toàn diện",'Tinh phi QL'!$E$13=0),KTVTDGTTKMH!M7,IF(AND('Tinh phi QL'!$H$12=0,'Tinh phi QL'!$B$13="Khỏe Bình An"),KBAGTTKMH!M7,IF(AND('Tinh phi QL'!$H$12=0,'Tinh phi QL'!$B$13="Vững Tương Lai"),VTLGTTKMH!M7,0)))))) -> 0
B4: 2 | C4: =IF(AND('Tinh phi QL'!$H$13=0,'Tinh phi QL'!$H$12<>0),IF(ROW(A2)>'Tinh phi QL'!$D$12,"",ROW(A2)),IF(ROW(A2)>'Tinh phi QL'!$D$12,"",ROW(A2))) -> 2 | D4: =MAX(IF(IFERROR(--TRIM(C4),0)=0,0,C4*IF(AND('Tinh phi QL'!$H$13=0,'Tinh phi QL'!$H$12<>0),'Tinh phi QL'!$H$12/1000,'Tinh phi QL'!$H$13/1000)),D3) -> 20000 | E4: =IF(AND('Tinh phi QL'!$B$12="Khỏe trọn vẹn - Tối ưu",'Tinh phi QL'!$E$13=0),KTVTUGTTKcamket!M8,IF(AND('Tinh phi QL'!$B$12="Khỏe trọn vẹn - bền vững",'Tinh phi QL'!$E$13=0),KTVBVGTTKcamket!M8,IF(AND('Tinh phi QL'!$B$12="Khỏe trọn vẹn - trọn đời",'Tinh phi QL'!$E$13=0),KTVTRDGTTKcamket!M8,IF(AND('Tinh phi QL'!$B$12="Khỏe trọn vẹn - toàn diện",'Tinh phi QL'!$E$13=0),KTVTDGTTKcamket!M8,IF(AND('Tinh phi QL'!$H$12=0,'Tinh phi QL'!$B$13="Khỏe Bình An"),KBAGTTKcamket!M8,IF(AND('Tinh phi QL'!$H$12=0,'Tinh phi QL'!$B$13="Vững Tương Lai"),VTLGTTKcamket!M8,0)))))) -> 0 | F4: =IF(AND('Tinh phi QL'!$B$12="Khỏe trọn vẹn - Tối ưu",'Tinh phi QL'!$E$13=0),KTVTUGTTKMH!M8,IF(AND('Tinh phi QL'!$B$12="Khỏe trọn vẹn - bền vững",'Tinh phi QL'!$E$13=0),KTVBVGTTKMH!M8,IF(AND('Tinh phi QL'!$B$12="Khỏe trọn vẹn - trọn đời",'Tinh phi QL'!$E$13=0),KTVTRDGTTKMH!M8,IF(AND('Tinh phi QL'!$B$12="Khỏe trọn vẹn - toàn diện",'Tinh phi QL'!$E$13=0),KTVTDGTTKMH!M8,IF(AND('Tinh phi QL'!$H$12=0,'Tinh phi QL'!$B$13="Khỏe Bình An"),KBAGTTKMH!M8,IF(AND('Tinh phi QL'!$H$12=0,'Tinh phi QL'!$B$13="Vững Tương Lai"),VTLGTTKMH!M8,0)))))) -> 0 | R4: =D2 -> Số phí sản phẩm chính lũy kế
B5: 3 | C5: =IF(AND('Tinh phi QL'!$H$13=0,'Tinh phi QL'!$H$12<>0),IF(ROW(A3)>'Tinh phi QL'!$D$12,"",ROW(A3)),IF(ROW(A3)>'Tinh phi QL'!$D$12,"",ROW(A3))) -> 3 | D5: =MAX(IF(IFERROR(--TRIM(C5),0)=0,0,C5*IF(AND('Tinh phi QL'!$H$13=0,'Tinh phi QL'!$H$12<>0),'Tinh phi QL'!$H$12/1000,'Tinh phi QL'!$H$13/1000)),D4) -> 30000 | E5: =IF(AND('Tinh phi QL'!$B$12="Khỏe trọn vẹn - Tối ưu",'Tinh phi QL'!$E$13=0),KTVTUGTTKcamket!M9,IF(AND('Tinh phi QL'!$B$12="Khỏe trọn vẹn - bền vững",'Tinh phi QL'!$E$13=0),KTVBVGTTKcamket!M9,IF(AND('Tinh phi QL'!$B$12="Khỏe trọn vẹn - trọn đời",'Tinh phi QL'!$E$13=0),KTVTRDGTTKcamket!M9,IF(AND('Tinh phi QL'!$B$12="Khỏe trọn vẹn - toàn diện",'Tinh phi QL'!$E$13=0),KTVTDGTTKcamket!M9,IF(AND('Tinh phi QL'!$H$12=0,'Tinh phi QL'!$B$13="Khỏe Bình An"),KBAGTTKcamket!M9,IF(AND('Tinh phi QL'!$H$12=0,'Tinh phi QL'!$B$13="Vững Tương Lai"),VTLGTTKcamket!M9,0)))))) -> 10424.154 | F5: =IF(AND('Tinh phi QL'!$B$12="Khỏe trọn vẹn - Tối ưu",'Tinh phi QL'!$E$13=0),KTVTUGTTKMH!M9,IF(AND('Tinh phi QL'!$B$12="Khỏe trọn vẹn - bền vững",'Tinh phi QL'!$E$13=0),KTVBVGTTKMH!M9,IF(AND('Tinh phi QL'!$B$12="Khỏe trọn vẹn - trọn đời",'Tinh phi QL'!$E$13=0),KTVTRDGTTKMH!M9,IF(AND('Tinh phi QL'!$B$12="Khỏe trọn vẹn - toàn diện",'Tinh phi QL'!$E$13=0),KTVTDGTTKMH!M9,IF(AND('Tinh phi QL'!$H$12=0,'Tinh phi QL'!$B$13="Khỏe Bình An"),KBAGTTKMH!M9,IF(AND('Tinh phi QL'!$H$12=0,'Tinh phi QL'!$B$13="Vững Tương Lai"),VTLGTTKMH!M9,0)))))) -> 10874.027 | R5: =E2 -> Giá trị hoàn lại LS cam kết
B6: 4 | C6: =IF(AND('Tinh phi QL'!$H$13=0,'Tinh phi QL'!$H$12<>0),IF(ROW(A4)>'Tinh phi QL'!$D$12,"",ROW(A4)),IF(ROW(A4)>'Tinh phi QL'!$D$12,"",ROW(A4))) -> 4 | D6: =MAX(IF(IFERROR(--TRIM(C6),0)=0,0,C6*IF(AND('Tinh phi QL'!$H$13=0,'Tinh phi QL'!$H$12<>0),'Tinh phi QL'!$H$12/1000,'Tinh phi QL'!$H$13/1000)),D5) -> 40000 | E6: =IF(AND('Tinh phi QL'!$B$12="Khỏe trọn vẹn - Tối ưu",'Tinh phi QL'!$E$13=0),KTVTUGTTKcamket!M10,IF(AND('Tinh phi QL'!$B$12="Khỏe trọn vẹn - bền vững",'Tinh phi QL'!$E$13=0),KTVBVGTTKcamket!M10,IF(AND('Tinh phi QL'!$B$12="Khỏe trọn vẹn - trọn đời",'Tinh phi QL'!$E$13=0),KTVTRDGTTKcamket!M10,IF(AND('Tinh phi QL'!$B$12="Khỏe trọn vẹn - toàn diện",'Tinh phi QL'!$E$13=0),KTVTDGTTKcamket!M10,IF(AND('Tinh phi QL'!$H$12=0,'Tinh phi QL'!$B$13="Khỏe Bình An"),KBAGTTKcamket!M10,IF(AND('Tinh phi QL'!$H$12=0,'Tinh phi QL'!$B$13="Vững Tương Lai"),VTLGTTKcamket!M10,0)))))) -> 18058.562 | F6: =IF(AND('Tinh phi QL'!$B$12="Khỏe trọn vẹn - Tối ưu",'Tinh phi QL'!$E$13=0),KTVTUGTTKMH!M10,IF(AND('Tinh phi QL'!$B$12="Khỏe trọn vẹn - bền vững",'Tinh phi QL'!$E$13=0),KTVBVGTTKMH!M10,IF(AND('Tinh phi QL'!$B$12="Khỏe trọn vẹn - trọn đời",'Tinh phi QL'!$E$13=0),KTVTRDGTTKMH!M10,IF(AND('Tinh phi QL'!$B$12="Khỏe trọn vẹn - toàn diện",'Tinh phi QL'!$E$13=0),KTVTDGTTKMH!M10,IF(AND('Tinh phi QL'!$H$12=0,'Tinh phi QL'!$B$13="Khỏe Bình An"),KBAGTTKMH!M10,IF(AND('Tinh phi QL'!$H$12=0,'Tinh phi QL'!$B$13="Vững Tương Lai"),VTLGTTKMH!M10,0)))))) -> 19094.635 | R6: =F2 -> Giá trị hoàn lại LS minh họa
B7: 5 | C7: =IF(AND('Tinh phi QL'!$H$13=0,'Tinh phi QL'!$H$12<>0),IF(ROW(A5)>'Tinh phi QL'!$D$12,"",ROW(A5)),IF(ROW(A5)>'Tinh phi QL'!$D$12,"",ROW(A5))) -> 5 | D7: =MAX(IF(IFERROR(--TRIM(C7),0)=0,0,C7*IF(AND('Tinh phi QL'!$H$13=0,'Tinh phi QL'!$H$12<>0),'Tinh phi QL'!$H$12/1000,'Tinh phi QL'!$H$13/1000)),D6) -> 50000 | E7: =IF(AND('Tinh phi QL'!$B$12="Khỏe trọn vẹn - Tối ưu",'Tinh phi QL'!$E$13=0),KTVTUGTTKcamket!M11,IF(AND('Tinh phi QL'!$B$12="Khỏe trọn vẹn - bền vững",'Tinh phi QL'!$E$13=0),KTVBVGTTKcamket!M11,IF(AND('Tinh phi QL'!$B$12="Khỏe trọn vẹn - trọn đời",'Tinh phi QL'!$E$13=0),KTVTRDGTTKcamket!M11,IF(AND('Tinh phi QL'!$B$12="Khỏe trọn vẹn - toàn diện",'Tinh phi QL'!$E$13=0),KTVTDGTTKcamket!M11,IF(AND('Tinh phi QL'!$H$12=0,'Tinh phi QL'!$B$13="Khỏe Bình An"),KBAGTTKcamket!M11,IF(AND('Tinh phi QL'!$H$12=0,'Tinh phi QL'!$B$13="Vững Tương Lai"),VTLGTTKcamket!M11,0)))))) -> 25390.684 | F7: =IF(AND('Tinh phi QL'!$B$12="Khỏe trọn vẹn - Tối ưu",'Tinh phi QL'!$E$13=0),KTVTUGTTKMH!M11,IF(AND('Tinh phi QL'!$B$12="Khỏe trọn vẹn - bền vững",'Tinh phi QL'!$E$13=0),KTVBVGTTKMH!M11,IF(AND('Tinh phi QL'!$B$12="Khỏe trọn vẹn - trọn đời",'Tinh phi QL'!$E$13=0),KTVTRDGTTKMH!M11,IF(AND('Tinh phi QL'!$B$12="Khỏe trọn vẹn - toàn diện",'Tinh phi QL'!$E$13=0),KTVTDGTTKMH!M11,IF(AND('Tinh phi QL'!$H$12=0,'Tinh phi QL'!$B$13="Khỏe Bình An"),KBAGTTKMH!M11,IF(AND('Tinh phi QL'!$H$12=0,'Tinh phi QL'!$B$13="Vững Tương Lai"),VTLGTTKMH!M11,0)))))) -> 27197.111
B8: 6 | C8: =IF(AND('Tinh phi QL'!$H$13=0,'Tinh phi QL'!$H$12<>0),IF(ROW(A6)>'Tinh phi QL'!$D$12,"",ROW(A6)),IF(ROW(A6)>'Tinh phi QL'!$D$12,"",ROW(A6))) -> 6 | D8: =MAX(IF(IFERROR(--TRIM(C8),0)=0,0,C8*IF(AND('Tinh phi QL'!$H$13=0,'Tinh phi QL'!$H$12<>0),'Tinh phi QL'!$H$12/1000,'Tinh phi QL'!$H$13/1000)),D7) -> 60000 | E8: =IF(AND('Tinh phi QL'!$B$12="Khỏe trọn vẹn - Tối ưu",'Tinh phi QL'!$E$13=0),KTVTUGTTKcamket!M12,IF(AND('Tinh phi QL'!$B$12="Khỏe trọn vẹn - bền vững",'Tinh phi QL'!$E$13=0),KTVBVGTTKcamket!M12,IF(AND('Tinh phi QL'!$B$12="Khỏe trọn vẹn - trọn đời",'Tinh phi QL'!$E$13=0),KTVTRDGTTKcamket!M12,IF(AND('Tinh phi QL'!$B$12="Khỏe trọn vẹn - toàn diện",'Tinh phi QL'!$E$13=0),KTVTDGTTKcamket!M12,IF(AND('Tinh phi QL'!$H$12=0,'Tinh phi QL'!$B$13="Khỏe Bình An"),KBAGTTKcamket!M12,IF(AND('Tinh phi QL'!$H$12=0,'Tinh phi QL'!$B$13="Vững Tương Lai"),VTLGTTKcamket!M12,0)))))) -> 35319.444 | F8: =IF(AND('Tinh phi QL'!$B$12="Khỏe trọn vẹn - Tối ưu",'Tinh phi QL'!$E$13=0),KTVTUGTTKMH!M12,IF(AND('Tinh phi QL'!$B$12="Khỏe trọn vẹn - bền vững",'Tinh phi QL'!$E$13=0),KTVBVGTTKMH!M12,IF(AND('Tinh phi QL'!$B$12="Khỏe trọn vẹn - trọn đời",'Tinh phi QL'!$E$13=0),KTVTRDGTTKMH!M12,IF(AND('Tinh phi QL'!$B$12="Khỏe trọn vẹn - toàn diện",'Tinh phi QL'!$E$13=0),KTVTDGTTKMH!M12,IF(AND('Tinh phi QL'!$H$12=0,'Tinh phi QL'!$B$13="Khỏe Bình An"),KBAGTTKMH!M12,IF(AND('Tinh phi QL'!$H$12=0,'Tinh phi QL'!$B$13="Vững Tương Lai"),VTLGTTKMH!M12,0)))))) -> 38321.025
B9: 7 | C9: =IF(AND('Tinh phi QL'!$H$13=0,'Tinh phi QL'!$H$12<>0),IF(ROW(A7)>'Tinh phi QL'!$D$12,"",ROW(A7)),IF(ROW(A7)>'Tinh phi QL'!$D$12,"",ROW(A7))) -> 7 | D9: =MAX(IF(IFERROR(--TRIM(C9),0)=0,0,C9*IF(AND('Tinh phi QL'!$H$13=0,'Tinh phi QL'!$H$12<>0),'Tinh phi QL'!$H$12/1000,'Tinh phi QL'!$H$13/1000)),D8) -> 70000 | E9: =IF(AND('Tinh phi QL'!$B$12="Khỏe trọn vẹn - Tối ưu",'Tinh phi QL'!$E$13=0),KTVTUGTTKcamket!M13,IF(AND('Tinh phi QL'!$B$12="Khỏe trọn vẹn - bền vững",'Tinh phi QL'!$E$13=0),KTVBVGTTKcamket!M13,IF(AND('Tinh phi QL'!$B$12="Khỏe trọn vẹn - trọn đời",'Tinh phi QL'!$E$13=0),KTVTRDGTTKcamket!M13,IF(AND('Tinh phi QL'!$B$12="Khỏe trọn vẹn - toàn diện",'Tinh phi QL'!$E$13=0),KTVTDGTTKcamket!M13,IF(AND('Tinh phi QL'!$H$12=0,'Tinh phi QL'!$B$13="Khỏe Bình An"),KBAGTTKcamket!M13,IF(AND('Tinh phi QL'!$H$12=0,'Tinh phi QL'!$B$13="Vững Tương Lai"),VTLGTTKcamket!M13,0)))))) -> 43141.491 | F9: =IF(AND('Tinh phi QL'!$B$12="Khỏe trọn vẹn - Tối ưu",'Tinh phi QL'!$E$13=0),KTVTUGTTKMH!M13,IF(AND('Tinh phi QL'!$B$12="Khỏe trọn vẹn - bền vững",'Tinh phi QL'!$E$13=0),KTVBVGTTKMH!M13,IF(AND('Tinh phi QL'!$B$12="Khỏe trọn vẹn - trọn đời",'Tinh phi QL'!$E$13=0),KTVTRDGTTKMH!M13,IF(AND('Tinh phi QL'!$B$12="Khỏe trọn vẹn - toàn diện",'Tinh phi QL'!$E$13=0),KTVTDGTTKMH!M13,IF(AND('Tinh phi QL'!$H$12=0,'Tinh phi QL'!$B$13="Khỏe Bình An"),KBAGTTKMH!M13,IF(AND('Tinh phi QL'!$H$12=0,'Tinh phi QL'!$B$13="Vững Tương Lai"),VTLGTTKMH!M13,0)))))) -> 47638.091
B10: 8 | C10: =IF(AND('Tinh phi QL'!$H$13=0,'Tinh phi QL'!$H$12<>0),IF(ROW(A8)>'Tinh phi QL'!$D$12,"",ROW(A8)),IF(ROW(A8)>'Tinh phi QL'!$D$12,"",ROW(A8))) -> 8 | D10: =MAX(IF(IFERROR(--TRIM(C10),0)=0,0,C10*IF(AND('Tinh phi QL'!$H$13=0,'Tinh phi QL'!$H$12<>0),'Tinh phi QL'!$H$12/1000,'Tinh phi QL'!$H$13/1000)),D9) -> 80000 | E10: =IF(AND('Tinh phi QL'!$B$12="Khỏe trọn vẹn - Tối ưu",'Tinh phi QL'!$E$13=0),KTVTUGTTKcamket!M14,IF(AND('Tinh phi QL'!$B$12="Khỏe trọn vẹn - bền vững",'Tinh phi QL'!$E$13=0),KTVBVGTTKcamket!M14,IF(AND('Tinh phi QL'!$B$12="Khỏe trọn vẹn - trọn đời",'Tinh phi QL'!$E$13=0),KTVTRDGTTKcamket!M14,IF(AND('Tinh phi QL'!$B$12="Khỏe trọn vẹn - toàn diện",'Tinh phi QL'!$E$13=0),KTVTDGTTKcamket!M14,IF(AND('Tinh phi QL'!$H$12=0,'Tinh phi QL'!$B$13="Khỏe Bình An"),KBAGTTKcamket!M14,IF(AND('Tinh phi QL'!$H$12=0,'Tinh phi QL'!$B$13="Vững Tương Lai"),VTLGTTKcamket!M14,0)))))) -> 50823.851 | F10: =IF(AND('Tinh phi QL'!$B$12="Khỏe trọn vẹn - Tối ưu",'Tinh phi QL'!$E$13=0),KTVTUGTTKMH!M14,IF(AND('Tinh phi QL'!$B$12="Khỏe trọn vẹn - bền vững",'Tinh phi QL'!$E$13=0),KTVBVGTTKMH!M14,IF(AND('Tinh phi QL'!$B$12="Khỏe trọn vẹn - trọn đời",'Tinh phi QL'!$E$13=0),KTVTRDGTTKMH!M14,IF(AND('Tinh phi QL'!$B$12="Khỏe trọn vẹn - toàn diện",'Tinh phi QL'!$E$13=0),KTVTDGTTKMH!M14,IF(AND('Tinh phi QL'!$H$12=0,'Tinh phi QL'!$B$13="Khỏe Bình An"),KBAGTTKMH!M14,IF(AND('Tinh phi QL'!$H$12=0,'Tinh phi QL'!$B$13="Vững Tương Lai"),VTLGTTKMH!M14,0)))))) -> 57126.335
B11: 9 | C11: =IF(AND('Tinh phi QL'!$H$13=0,'Tinh phi QL'!$H$12<>0),IF(ROW(A9)>'Tinh phi QL'!$D$12,"",ROW(A9)),IF(ROW(A9)>'Tinh phi QL'!$D$12,"",ROW(A9))) -> 9 | D11: =MAX(IF(IFERROR(--TRIM(C11),0)=0,0,C11*IF(AND('Tinh phi QL'!$H$13=0,'Tinh phi QL'!$H$12<>0),'Tinh phi QL'!$H$12/1000,'Tinh phi QL'!$H$13/1000)),D10) -> 90000 | E11: =IF(AND('Tinh phi QL'!$B$12="Khỏe trọn vẹn - Tối ưu",'Tinh phi QL'!$E$13=0),KTVTUGTTKcamket!M15,IF(AND('Tinh phi QL'!$B$12="Khỏe trọn vẹn - bền vững",'Tinh phi QL'!$E$13=0),KTVBVGTTKcamket!M15,IF(AND('Tinh phi QL'!$B$12="Khỏe trọn vẹn - trọn đời",'Tinh phi QL'!$E$13=0),KTVTRDGTTKcamket!M15,IF(AND('Tinh phi QL'!$B$12="Khỏe trọn vẹn - toàn diện",'Tinh phi QL'!$E$13=0),KTVTDGTTKcamket!M15,IF(AND('Tinh phi QL'!$H$12=0,'Tinh phi QL'!$B$13="Khỏe Bình An"),KBAGTTKcamket!M15,IF(AND('Tinh phi QL'!$H$12=0,'Tinh phi QL'!$B$13="Vững Tương Lai"),VTLGTTKcamket!M15,0)))))) -> 58270.601 | F11: =IF(AND('Tinh phi QL'!$B$12="Khỏe trọn vẹn - Tối ưu",'Tinh phi QL'!$E$13=0),KTVTUGTTKMH!M15,IF(AND('Tinh phi QL'!$B$12="Khỏe trọn vẹn - bền vững",'Tinh phi QL'!$E$13=0),KTVBVGTTKMH!M15,IF(AND('Tinh phi QL'!$B$12="Khỏe trọn vẹn - trọn đời",'Tinh phi QL'!$E$13=0),KTVTRDGTTKMH!M15,IF(AND('Tinh phi QL'!$B$12="Khỏe trọn vẹn - toàn diện",'Tinh phi QL'!$E$13=0),KTVTDGTTKMH!M15,IF(AND('Tinh phi QL'!$H$12=0,'Tinh phi QL'!$B$13="Khỏe Bình An"),KBAGTTKMH!M15,IF(AND('Tinh phi QL'!$H$12=0,'Tinh phi QL'!$B$13="Vững Tương Lai"),VTLGTTKMH!M15,0)))))) -> 66699.982
B12: 10 | C12: =IF(AND('Tinh phi QL'!$H$13=0,'Tinh phi QL'!$H$12<>0),IF(ROW(A10)>'Tinh phi QL'!$D$12,"",ROW(A10)),IF(ROW(A10)>'Tinh phi QL'!$D$12,"",ROW(A10))) -> 10 | D12: =MAX(IF(IFERROR(--TRIM(C12),0)=0,0,C12*IF(AND('Tinh phi QL'!$H$13=0,'Tinh phi QL'!$H$12<>0),'Tinh phi QL'!$H$12/1000,'Tinh phi QL'!$H$13/1000)),D11) -> 100000 | E12: =IF(AND('Tinh phi QL'!$B$12="Khỏe trọn vẹn - Tối ưu",'Tinh phi QL'!$E$13=0),KTVTUGTTKcamket!M16,IF(AND('Tinh phi QL'!$B$12="Khỏe trọn vẹn - bền vững",'Tinh phi QL'!$E$13=0),KTVBVGTTKcamket!M16,IF(AND('Tinh phi QL'!$B$12="Khỏe trọn vẹn - trọn đời",'Tinh phi QL'!$E$13=0),KTVTRDGTTKcamket!M16,IF(AND('Tinh phi QL'!$B$12="Khỏe trọn vẹn - toàn diện",'Tinh phi QL'!$E$13=0),KTVTDGTTKcamket!M16,IF(AND('Tinh phi QL'!$H$12=0,'Tinh phi QL'!$B$13="Khỏe Bình An"),KBAGTTKcamket!M16,IF(AND('Tinh phi QL'!$H$12=0,'Tinh phi QL'!$B$13="Vững Tương Lai"),VTLGTTKcamket!M16,0)))))) -> 65430.624 | F12: =IF(AND('Tinh phi QL'!$B$12="Khỏe trọn vẹn - Tối ưu",'Tinh phi QL'!$E$13=0),KTVTUGTTKMH!M16,IF(AND('Tinh phi QL'!$B$12="Khỏe trọn vẹn - bền vững",'Tinh phi QL'!$E$13=0),KTVBVGTTKMH!M16,IF(AND('Tinh phi QL'!$B$12="Khỏe trọn vẹn - trọn đời",'Tinh phi QL'!$E$13=0),KTVTRDGTTKMH!M16,IF(AND('Tinh phi QL'!$B$12="Khỏe trọn vẹn - toàn diện",'Tinh phi QL'!$E$13=0),KTVTDGTTKMH!M16,IF(AND('Tinh phi QL'!$H$12=0,'Tinh phi QL'!$B$13="Khỏe Bình An"),KBAGTTKMH!M16,IF(AND('Tinh phi QL'!$H$12=0,'Tinh phi QL'!$B$13="Vững Tương Lai"),VTLGTTKMH!M16,0)))))) -> 76315.273
B13: 11 | C13: =IF(AND('Tinh phi QL'!$H$13=0,'Tinh phi QL'!$H$12<>0),IF(ROW(A11)>'Tinh phi QL'!$D$12,"",ROW(A11)),IF(ROW(A11)>'Tinh phi QL'!$D$12,"",ROW(A11))) -> 11 | D13: =MAX(IF(IFERROR(--TRIM(C13),0)=0,0,C13*IF(AND('Tinh phi QL'!$H$13=0,'Tinh phi QL'!$H$12<>0),'Tinh phi QL'!$H$12/1000,'Tinh phi QL'!$H$13/1000)),D12) -> 110000 | E13: =IF(AND('Tinh phi QL'!$B$12="Khỏe trọn vẹn - Tối ưu",'Tinh phi QL'!$E$13=0),KTVTUGTTKcamket!M17,IF(AND('Tinh phi QL'!$B$12="Khỏe trọn vẹn - bền vững",'Tinh phi QL'!$E$13=0),KTVBVGTTKcamket!M17,IF(AND('Tinh phi QL'!$B$12="Khỏe trọn vẹn - trọn đời",'Tinh phi QL'!$E$13=0),KTVTRDGTTKcamket!M17,IF(AND('Tinh phi QL'!$B$12="Khỏe trọn vẹn - toàn diện",'Tinh phi QL'!$E$13=0),KTVTDGTTKcamket!M17,IF(AND('Tinh phi QL'!$H$12=0,'Tinh phi QL'!$B$13="Khỏe Bình An"),KBAGTTKcamket!M17,IF(AND('Tinh phi QL'!$H$12=0,'Tinh phi QL'!$B$13="Vững Tương Lai"),VTLGTTKcamket!M17,0)))))) -> 72147.562 | F13: =IF(AND('Tinh phi QL'!$B$12="Khỏe trọn vẹn - Tối ưu",'Tinh phi QL'!$E$13=0),KTVTUGTTKMH!M17,IF(AND('Tinh phi QL'!$B$12="Khỏe trọn vẹn - bền vững",'Tinh phi QL'!$E$13=0),KTVBVGTTKMH!M17,IF(AND('Tinh phi QL'!$B$12="Khỏe trọn vẹn - trọn đời",'Tinh phi QL'!$E$13=0),KTVTRDGTTKMH!M17,IF(AND('Tinh phi QL'!$B$12="Khỏe trọn vẹn - toàn diện",'Tinh phi QL'!$E$13=0),KTVTDGTTKMH!M17,IF(AND('Tinh phi QL'!$H$12=0,'Tinh phi QL'!$B$13="Khỏe Bình An"),KBAGTTKMH!M17,IF(AND('Tinh phi QL'!$H$12=0,'Tinh phi QL'!$B$13="Vững Tương Lai"),VTLGTTKMH!M17,0)))))) -> 86196.831
B14: 12 | C14: =IF(AND('Tinh phi QL'!$H$13=0,'Tinh phi QL'!$H$12<>0),IF(ROW(A12)>'Tinh phi QL'!$D$12,"",ROW(A12)),IF(ROW(A12)>'Tinh phi QL'!$D$12,"",ROW(A12))) -> 12 | D14: =MAX(IF(IFERROR(--TRIM(C14),0)=0,0,C14*IF(AND('Tinh phi QL'!$H$13=0,'Tinh phi QL'!$H$12<>0),'Tinh phi QL'!$H$12/1000,'Tinh phi QL'!$H$13/1000)),D13) -> 120000 | E14: =IF(AND('Tinh phi QL'!$B$12="Khỏe trọn vẹn - Tối ưu",'Tinh phi QL'!$E$13=0),KTVTUGTTKcamket!M18,IF(AND('Tinh phi QL'!$B$12="Khỏe trọn vẹn - bền vững",'Tinh phi QL'!$E$13=0),KTVBVGTTKcamket!M18,IF(AND('Tinh phi QL'!$B$12="Khỏe trọn vẹn - trọn đời",'Tinh phi QL'!$E$13=0),KTVTRDGTTKcamket!M18,IF(AND('Tinh phi QL'!$B$12="Khỏe trọn vẹn - toàn diện",'Tinh phi QL'!$E$13=0),KTVTDGTTKcamket!M18,IF(AND('Tinh phi QL'!$H$12=0,'Tinh phi QL'!$B$13="Khỏe Bình An"),KBAGTTKcamket!M18,IF(AND('Tinh phi QL'!$H$12=0,'Tinh phi QL'!$B$13="Vững Tương Lai"),VTLGTTKcamket!M18,0)))))) -> 78640.138 | F14: =IF(AND('Tinh phi QL'!$B$12="Khỏe trọn vẹn - Tối ưu",'Tinh phi QL'!$E$13=0),KTVTUGTTKMH!M18,IF(AND('Tinh phi QL'!$B$12="Khỏe trọn vẹn - bền vững",'Tinh phi QL'!$E$13=0),KTVBVGTTKMH!M18,IF(AND('Tinh phi QL'!$B$12="Khỏe trọn vẹn - trọn đời",'Tinh phi QL'!$E$13=0),KTVTRDGTTKMH!M18,IF(AND('Tinh phi QL'!$B$12="Khỏe trọn vẹn - toàn diện",'Tinh phi QL'!$E$13=0),KTVTDGTTKMH!M18,IF(AND('Tinh phi QL'!$H$12=0,'Tinh phi QL'!$B$13="Khỏe Bình An"),KBAGTTKMH!M18,IF(AND('Tinh phi QL'!$H$12=0,'Tinh phi QL'!$B$13="Vững Tương Lai"),VTLGTTKMH!M18,0)))))) -> 96247.906
B15: 13 | C15: =IF(AND('Tinh phi QL'!$H$13=0,'Tinh phi QL'!$H$12<>0),IF(ROW(A13)>'Tinh phi QL'!$D$12,"",ROW(A13)),IF(ROW(A13)>'Tinh phi QL'!$D$12,"",ROW(A13))) -> 13 | D15: =MAX(IF(IFERROR(--TRIM(C15),0)=0,0,C15*IF(AND('Tinh phi QL'!$H$13=0,'Tinh phi QL'!$H$12<>0),'Tinh phi QL'!$H$12/1000,'Tinh phi QL'!$H$13/1000)),D14) -> 130000 | E15: =IF(AND('Tinh phi QL'!$B$12="Khỏe trọn vẹn - Tối ưu",'Tinh phi QL'!$E$13=0),KTVTUGTTKcamket!M19,IF(AND('Tinh phi QL'!$B$12="Khỏe trọn vẹn - bền vững",'Tinh phi QL'!$E$13=0),KTVBVGTTKcamket!M19,IF(AND('Tinh phi QL'!$B$12="Khỏe trọn vẹn - trọn đời",'Tinh phi QL'!$E$13=0),KTVTRDGTTKcamket!M19,IF(AND('Tinh phi QL'!$B$12="Khỏe trọn vẹn - toàn diện",'Tinh phi QL'!$E$13=0),KTVTDGTTKcamket!M19,IF(AND('Tinh phi QL'!$H$12=0,'Tinh phi QL'!$B$13="Khỏe Bình An"),KBAGTTKcamket!M19,IF(AND('Tinh phi QL'!$H$12=0,'Tinh phi QL'!$B$13="Vững Tương Lai"),VTLGTTKcamket!M19,0)))))) -> 84885.551 | F15: =IF(AND('Tinh phi QL'!$B$12="Khỏe trọn vẹn - Tối ưu",'Tinh phi QL'!$E$13=0),KTVTUGTTKMH!M19,IF(AND('Tinh phi QL'!$B$12="Khỏe trọn vẹn - bền vững",'Tinh phi QL'!$E$13=0),KTVBVGTTKMH!M19,IF(AND('Tinh phi QL'!$B$12="Khỏe trọn vẹn - trọn đời",'Tinh phi QL'!$E$13=0),KTVTRDGTTKMH!M19,IF(AND('Tinh phi QL'!$B$12="Khỏe trọn vẹn - toàn diện",'Tinh phi QL'!$E$13=0),KTVTDGTTKMH!M19,IF(AND('Tinh phi QL'!$H$12=0,'Tinh phi QL'!$B$13="Khỏe Bình An"),KBAGTTKMH!M19,IF(AND('Tinh phi QL'!$H$12=0,'Tinh phi QL'!$B$13="Vững Tương Lai"),VTLGTTKMH!M19,0)))))) -> 106458.35
B16: 14 | C16: =IF(AND('Tinh phi QL'!$H$13=0,'Tinh phi QL'!$H$12<>0),IF(ROW(A14)>'Tinh phi QL'!$D$12,"",ROW(A14)),IF(ROW(A14)>'Tinh phi QL'!$D$12,"",ROW(A14))) -> 14 | D16: =MAX(IF(IFERROR(--TRIM(C16),0)=0,0,C16*IF(AND('Tinh phi QL'!$H$13=0,'Tinh phi QL'!$H$12<>0),'Tinh phi QL'!$H$12/1000,'Tinh phi QL'!$H$13/1000)),D15) -> 140000 | E16: =IF(AND('Tinh phi QL'!$B$12="Khỏe trọn vẹn - Tối ưu",'Tinh phi QL'!$E$13=0),KTVTUGTTKcamket!M20,IF(AND('Tinh phi QL'!$B$12="Khỏe trọn vẹn - bền vững",'Tinh phi QL'!$E$13=0),KTVBVGTTKcamket!M20,IF(AND('Tinh phi QL'!$B$12="Khỏe trọn vẹn - trọn đời",'Tinh phi QL'!$E$13=0),KTVTRDGTTKcamket!M20,IF(AND('Tinh phi QL'!$B$12="Khỏe trọn vẹn - toàn diện",'Tinh phi QL'!$E$13=0),KTVTDGTTKcamket!M20,IF(AND('Tinh phi QL'!$H$12=0,'Tinh phi QL'!$B$13="Khỏe Bình An"),KBAGTTKcamket!M20,IF(AND('Tinh phi QL'!$H$12=0,'Tinh phi QL'!$B$13="Vững Tương Lai"),VTLGTTKcamket!M20,0)))))) -> 90849.508 | F16: =IF(AND('Tinh phi QL'!$B$12="Khỏe trọn vẹn - Tối ưu",'Tinh phi QL'!$E$13=0),KTVTUGTTKMH!M20,IF(AND('Tinh phi QL'!$B$12="Khỏe trọn vẹn - bền vững",'Tinh phi QL'!$E$13=0),KTVBVGTTKMH!M20,IF(AND('Tinh phi QL'!$B$12="Khỏe trọn vẹn - trọn đời",'Tinh phi QL'!$E$13=0),KTVTRDGTTKMH!M20,IF(AND('Tinh phi QL'!$B$12="Khỏe trọn vẹn - toàn diện",'Tinh phi QL'!$E$13=0),KTVTDGTTKMH!M20,IF(AND('Tinh phi QL'!$H$12=0,'Tinh phi QL'!$B$13="Khỏe Bình An"),KBAGTTKMH!M20,IF(AND('Tinh phi QL'!$H$12=0,'Tinh phi QL'!$B$13="Vững Tương Lai"),VTLGTTKMH!M20,0)))))) -> 116806.77
B17: 15 | C17: =IF(AND('Tinh phi QL'!$H$13=0,'Tinh phi QL'!$H$12<>0),IF(ROW(A15)>'Tinh phi QL'!$D$12,"",ROW(A15)),IF(ROW(A15)>'Tinh phi QL'!$D$12,"",ROW(A15))) -> 15 | D17: =MAX(IF(IFERROR(--TRIM(C17),0)=0,0,C17*IF(AND('Tinh phi QL'!$H$13=0,'Tinh phi QL'!$H$12<>0),'Tinh phi QL'!$H$12/1000,'Tinh phi QL'!$H$13/1000)),D16) -> 150000 | E17: =IF(AND('Tinh phi QL'!$B$12="Khỏe trọn vẹn - Tối ưu",'Tinh phi QL'!$E$13=0),KTVTUGTTKcamket!M21,IF(AND('Tinh phi QL'!$B$12="Khỏe trọn vẹn - bền vững",'Tinh phi QL'!$E$13=0),KTVBVGTTKcamket!M21,IF(AND('Tinh phi QL'!$B$12="Khỏe trọn vẹn - trọn đời",'Tinh phi QL'!$E$13=0),KTVTRDGTTKcamket!M21,IF(AND('Tinh phi QL'!$B$12="Khỏe trọn vẹn - toàn diện",'Tinh phi QL'!$E$13=0),KTVTDGTTKcamket!M21,IF(AND('Tinh phi QL'!$H$12=0,'Tinh phi QL'!$B$13="Khỏe Bình An"),KBAGTTKcamket!M21,IF(AND('Tinh phi QL'!$H$12=0,'Tinh phi QL'!$B$13="Vững Tương Lai"),VTLGTTKcamket!M21,0)))))) -> 96508.779 | F17: =IF(AND('Tinh phi QL'!$B$12="Khỏe trọn vẹn - Tối ưu",'Tinh phi QL'!$E$13=0),KTVTUGTTKMH!M21,IF(AND('Tinh phi QL'!$B$12="Khỏe trọn vẹn - bền vững",'Tinh phi QL'!$E$13=0),KTVBVGTTKMH!M21,IF(AND('Tinh phi QL'!$B$12="Khỏe trọn vẹn - trọn đời",'Tinh phi QL'!$E$13=0),KTVTRDGTTKMH!M21,IF(AND('Tinh phi QL'!$B$12="Khỏe trọn vẹn - toàn diện",'Tinh phi QL'!$E$13=0),KTVTDGTTKMH!M21,IF(AND('Tinh phi QL'!$H$12=0,'Tinh phi QL'!$B$13="Khỏe Bình An"),KBAGTTKMH!M21,IF(AND('Tinh phi QL'!$H$12=0,'Tinh phi QL'!$B$13="Vững Tương Lai"),VTLGTTKMH!M21,0)))))) -> 127282.87
B18: 16 | C18: =IF(AND('Tinh phi QL'!$H$13=0,'Tinh phi QL'!$H$12<>0),IF(ROW(A16)>'Tinh phi QL'!$D$12,"",ROW(A16)),IF(ROW(A16)>'Tinh phi QL'!$D$12,"",ROW(A16))) | D18: =MAX(IF(IFERROR(--TRIM(C18),0)=0,0,C18*IF(AND('Tinh phi QL'!$H$13=0,'Tinh phi QL'!$H$12<>0),'Tinh phi QL'!$H$12/1000,'Tinh phi QL'!$H$13/1000)),D17) -> 150000 | E18: =IF(AND('Tinh phi QL'!$B$12="Khỏe trọn vẹn - Tối ưu",'Tinh phi QL'!$E$13=0),KTVTUGTTKcamket!M22,IF(AND('Tinh phi QL'!$B$12="Khỏe trọn vẹn - bền vững",'Tinh phi QL'!$E$13=0),KTVBVGTTKcamket!M22,IF(AND('Tinh phi QL'!$B$12="Khỏe trọn vẹn - trọn đời",'Tinh phi QL'!$E$13=0),KTVTRDGTTKcamket!M22,IF(AND('Tinh phi QL'!$B$12="Khỏe trọn vẹn - toàn diện",'Tinh phi QL'!$E$13=0),KTVTDGTTKcamket!M22,IF(AND('Tinh phi QL'!$H$12=0,'Tinh phi QL'!$B$13="Khỏe Bình An"),KBAGTTKcamket!M22,IF(AND('Tinh phi QL'!$H$12=0,'Tinh phi QL'!$B$13="Vững Tương Lai"),VTLGTTKcamket!M22,0)))))) -> 101322.62 | F18: =IF(AND('Tinh phi QL'!$B$12="Khỏe trọn vẹn - Tối ưu",'Tinh phi QL'!$E$13=0),KTVTUGTTKMH!M22,IF(AND('Tinh phi QL'!$B$12="Khỏe trọn vẹn - bền vững",'Tinh phi QL'!$E$13=0),KTVBVGTTKMH!M22,IF(AND('Tinh phi QL'!$B$12="Khỏe trọn vẹn - trọn đời",'Tinh phi QL'!$E$13=0),KTVTRDGTTKMH!M22,IF(AND('Tinh phi QL'!$B$12="Khỏe trọn vẹn - toàn diện",'Tinh phi QL'!$E$13=0),KTVTDGTTKMH!M22,IF(AND('Tinh phi QL'!$H$12=0,'Tinh phi QL'!$B$13="Khỏe Bình An"),KBAGTTKMH!M22,IF(AND('Tinh phi QL'!$H$12=0,'Tinh phi QL'!$B$13="Vững Tương Lai"),VTLGTTKMH!M22,0)))))) -> 137876.46
... B22: 20 | C22: =IF(AND('Tinh phi QL'!$H$13=0,'Tinh phi QL'!$H$12<>0),IF(ROW(A20)>'Tinh phi QL'!$D$12,"",ROW(A20)),IF(ROW(A20)>'Tinh phi QL'!$D$12,"",ROW(A20))) | D22: =MAX(IF(IFERROR(--TRIM(C22),0)=0,0,C22*IF(AND('Tinh phi QL'!$H$13=0,'Tinh phi QL'!$H$12<>0),'Tinh phi QL'!$H$12/1000,'Tinh phi QL'!$H$13/1000)),D21) -> 150000 | E22: =IF(AND('Tinh phi QL'!$B$12="Khỏe trọn vẹn - Tối ưu",'Tinh phi QL'!$E$13=0),KTVTUGTTKcamket!M26,IF(AND('Tinh phi QL'!$B$12="Khỏe trọn vẹn - bền vững",'Tinh phi QL'!$E$13=0),KTVBVGTTKcamket!M26,IF(AND('Tinh phi QL'!$B$12="Khỏe trọn vẹn - trọn đời",'Tinh phi QL'!$E$13=0),KTVTRDGTTKcamket!M26,IF(AND('Tinh phi QL'!$B$12="Khỏe trọn vẹn - toàn diện",'Tinh phi QL'!$E$13=0),KTVTDGTTKcamket!M26,IF(AND('Tinh phi QL'!$H$12=0,'Tinh phi QL'!$B$13="Khỏe Bình An"),KBAGTTKcamket!M26,IF(AND('Tinh phi QL'!$H$12=0,'Tinh phi QL'!$B$13="Vững Tương Lai"),VTLGTTKcamket!M26,0)))))) -> 116341.68 | F22: =IF(AND('Tinh phi QL'!$B$12="Khỏe trọn vẹn - Tối ưu",'Tinh phi QL'!$E$13=0),KTVTUGTTKMH!M26,IF(AND('Tinh phi QL'!$B$12="Khỏe trọn vẹn - bền vững",'Tinh phi QL'!$E$13=0),KTVBVGTTKMH!M26,IF(AND('Tinh phi QL'!$B$12="Khỏe trọn vẹn - trọn đời",'Tinh phi QL'!$E$13=0),KTVTRDGTTKMH!M26,IF(AND('Tinh phi QL'!$B$12="Khỏe trọn vẹn - toàn diện",'Tinh phi QL'!$E$13=0),KTVTDGTTKMH!M26,IF(AND('Tinh phi QL'!$H$12=0,'Tinh phi QL'!$B$13="Khỏe Bình An"),KBAGTTKMH!M26,IF(AND('Tinh phi QL'!$H$12=0,'Tinh phi QL'!$B$13="Vững Tương Lai"),VTLGTTKMH!M26,0)))))) -> 181045.17

Sheet Tom Tat QL
B1: Khách hàng | D1: ='Tinh phi QL'!F7 -> TRAN VAN HUY
B2: Tổng số phí đóng năm đầu tiên: | C2: ='Tinh phi QL'!H3 -> 16571000
B3: Tư vấn viên: | C3: ='Tinh phi QL'!C2 -> Phạm Quang Hà
B4: Mã số: | C4: ='Tinh phi QL'!F2 -> 101012337
B5: Mobile: | C5: =Start!C3 -> 0981984554
B6: Email: | C6: =Start!D3 -> quangha1659@gmail.com
B7: Tóm Tắt Quyền Lợi Bảo Hiểm | D7: =IF(AND('Tinh phi QL'!H12<>0,'Tinh phi QL'!H13=0),'Tinh phi QL'!B12,'Tinh phi QL'!B13) -> Khỏe Bình An
B8: Tên Quyền lợi | D8: ='Tinh phi QL'!F7 -> TRAN VAN HUY | E8: ='Tinh phi QL'!F28 -> Đỗ Thị X | F8: ='Tinh phi QL'!F48 -> Trần Huy A | G8: ='Tinh phi QL'!F67 -> Trần Huy B
B9: Số tiền bảo hiểm sản phẩm chính | D9: =MAX('Tinh phi QL'!E12,'Tinh phi QL'!E13) -> 1000000000
B10: TTTBVV trước khi đạt 75 tuổi hoặc từ ngày đạt 75 tuổi cho đến trước Ngày kỷ niệm hợp đồng kế tiếp
B11: Quyền lợi bảo hiểm TTTBVV do ung thư tuyến giáp
B12: Quyền lợi bảo hiểm TTTBVV do ung thư tuyến giáp giai đoạn sớm: | D12: =MIN(D9*10%,200000000) -> 100000000
B13: Quyền lợi bảo hiểm TTTBVV do ung thư tuyến giáp giai đoạn nghiêm trọng: | D13: Nhận số lớn hơn của STBH và GTTK HĐ – Quyền lợi bảo hiểm TTTBVV do UT TG GĐS đã chi trả (nếu có)
B14: Quyền lợi bảo hiểm TTTBVV không do ung thư tuyến giáp | D14: Nhận số lớn hơn của STBH & GTTK HĐ
B15: 1.2. Tử vong | D15: Nhận số lớn hơn của STBH & GTTK HĐ
B16: ='Tinh phi QL'!B14 -> Bảo hiểm Tử vong và thương tật do tai nạn | D16: ='Tinh phi QL'!G14 -> 500000000 | E16: ='Tinh phi QL'!G33 -> 0 | F16: ='Tinh phi QL'!G53 -> 0 | G16: ='Tinh phi QL'!G72 -> 0
B17: Quyền lợi tử vong, tàn tật hoặc bỏng do tai nạn tối đa | D17: =D16 -> 500000000 | E17: =E16 -> 0 | F17: =F16 -> 0 | G17: =G16 -> 0
B18: Quyền lợi tàn tật toàn bộ tạm thời do tai nạn theo tỉ lệ % của: | D18: =D16 -> 500000000 | E18: =E16 -> 0 | F18: =F16 -> 0 | G18: =G16 -> 0
B19: Quyền lợi bồi thường gấp đôi khi tử vong trong trường hợp đặc biệt | D19: =D18*2 -> 1000000000 | E19: =E18*2 -> 0 | F19: =F18*2 -> 0 | G19: =G18*2 -> 0
B20: ='Tinh phi QL'!B15 -> Bảo hiểm Hỗ trợ chi phí nằm viện | D20: ='Tinh phi QL'!G15 -> 0 | E20: ='Tinh phi QL'!G34 -> 0 | F20: ='Tinh phi QL'!G54 -> 0 | G20: ='Tinh phi QL'!G73 -> 0
B21: Nằm viện ở bệnh viện tuyến trung ương, tuyến tỉnh; hoặc - nằm ở bệnh viện tuyến huyện nơi có đăng ký Bảo hiểm y tế (BHYT); hoặc - nằm ở bệnh viện tuyến huyện để điều trị thương tích do tai nạn | D21: =D20 -> 0 | E21: =E20 -> 0 | F21: =F20 -> 0 | G21: =G20 -> 0
B22: Nằm viện ở bệnh viện tuyến huyện nơi không có đăng ký Bảo hiểm y tế (BHYT) hoặc không điều trị thương tích do tai nạn | D22: =D21/2 -> 0 | E22: =E21/2 -> 0 | F22: =F21/2 -> 0 | G22: =G21/2 -> 0
B23: Trợ cấp khi nằm tại khoa săn sóc đặc biệt Tối đa là 25 ngày cho cùng một lần nằm viện | D23: =D20*2 -> 0 | E23: =E20*2 -> 0 | F23: =F20*2 -> 0 | G23: =G20*2 -> 0
B24: ='Tinh phi QL'!B35 -> Bảo hiểm Toàn diện Bệnh hiểm nghèo 2.0 | D24: ='Tinh phi QL'!G16 -> 300000000 | E24: ='Tinh phi QL'!G35 -> 0 | F24: ='Tinh phi QL'!G55 -> 0 | G24: ='Tinh phi QL'!G74 -> 0
B25: Quyền lợi Bệnh hiểm nghèo giai đoạn sớm | D25: =D24*0.3 -> 90000000 | E25: =E24*0.3 -> 0 | F25: =F24*0.3 -> 0 | G25: =G24*0.3 -> 0
B26: Quyền lợi Bệnh hiểm nghèo giai đoạn giữa | D26: =D24*0.6 -> 180000000 | E26: =E24*0.6 -> 0 | F26: =F24*0.6 -> 0 | G26: =G24*0.6 -> 0
B27: Quyền lợi Bệnh hiểm nghèo giai đoạn nghiêm trọng | D27: =D24 -> 300000000 | E27: =E24 -> 0 | F27: =F24 -> 0 | G27: =G24 -> 0
B28: Quyền lợi Bệnh hiểm nghèo của trẻ em | D28: =D26 -> 180000000 | E28: =E26 -> 0 | F28: =F26 -> 0 | G28: =G26 -> 0
B29: Quyền lợi Bệnh hiểm nghèo dành cho người lớn tuổi | D29: =D24*0.2 -> 60000000 | E29: =E24*0.2 -> 0 | F29: =F24*0.2 -> 0 | G29: =G24*0.2 -> 0
B30: ='Tinh phi QL'!B25 -> Bảo hiểm tử kỳ gia hạn hàng năm | D30: ='Tinh phi QL'!G25 -> 0 | E30: ='Tinh phi QL'!G44 -> 0 | F30: ='Tinh phi QL'!G64 -> 0 | G30: ='Tinh phi QL'!G83 -> 0
B31: Bảo hiểm chăm sóc sức khỏe Trọn đời - Nội Trú | D31: ='Tinh phi QL'!G17 -> Nâng cao | E31: ='Tinh phi QL'!G36 -> 0 | F31: ='Tinh phi QL'!G56 -> 0 | G31: ='Tinh phi QL'!G75 -> 0
B32: Hạn mức mỗi năm (nhân đôi bảo vệ bệnh viện công áp dụng khi đã chi trả hết trong năm) | D32: =IF(D31=0,0,VLOOKUP('Tinh phi QL'!$G$17,The!$A$6:$R$9,2,0)) -> 350000000 | E32: =IF(E31=0,0,VLOOKUP('Tinh phi QL'!$G$36,The!$A$6:$R$9,2,0)) -> 0 | F32: =IF(F31=0,0,VLOOKUP('Tinh phi QL'!$G$56,The!$A$6:$R$9,2,0)) -> 0 | G32: =IF(G31=0,0,VLOOKUP('Tinh phi QL'!$G$75,The!$A$6:$R$9,2,0)) -> 0
B33: Phòng, giường bệnh (tối đa 100 ngày/ năm) | D33: =IF(D31=0,0,VLOOKUP('Tinh phi QL'!$G$17,The!$A$6:$R$9,3,0)) -> 2000000 | E33: =IF(E31=0,0,VLOOKUP('Tinh phi QL'!$G$36,The!$A$6:$R$9,3,0)) -> 0 | F33: =IF(F31=0,0,VLOOKUP('Tinh phi QL'!$G$56,The!$A$6:$R$9,3,0)) -> 0 | G33: =IF(G31=0,0,VLOOKUP('Tinh phi QL'!$G$75,The!$A$6:$R$9,3,0)) -> 0
B34: Phòng chăm sóc đặc biệt (tối đa 30 ngày/ năm) | D34: =IF(D31=0,0,VLOOKUP('Tinh phi QL'!$G$17,The!$A$6:$R$9,4,0)) -> Chi phí thực tế | E34: =IF(E31=0,0,VLOOKUP('Tinh phi QL'!$G$36,The!$A$6:$R$9,4,0)) -> 0 | F34: =IF(F31=0,0,VLOOKUP('Tinh phi QL'!$G$56,The!$A$6:$R$9,4,0)) -> 0 | G34: =IF(G31=0,0,VLOOKUP('Tinh phi QL'!$G$75,The!$A$6:$R$9,4,0)) -> 0
B35: Giường dành cho người thân (tối đa 30 ngày/năm).Chỉ áp dụng cho 1 người thân lưu lại cùng NĐBH dưới 18 tuổi hoặc NĐBH từ 60 tuổi trở lên | D35: =IF(D31=0,0,VLOOKUP('Tinh phi QL'!$G$17,The!$A$6:$R$9,5,0)) -> 250000 | E35: =IF(E31=0,0,VLOOKUP('Tinh phi QL'!$G$36,The!$A$6:$R$9,5,0)) -> 0 | F35: =IF(F31=0,0,VLOOKUP('Tinh phi QL'!$G$56,The!$A$6:$R$9,5,0)) -> 0 | G35: =IF(G31=0,0,VLOOKUP('Tinh phi QL'!$G$75,The!$A$6:$R$9,5,0)) -> 0
B36: Hỗ trợ chi phí nằm viện khi sử dụng bảo hiểm y tế (tối đa 30 ngày/năm) | D36: =IF(D31="cơ bản",150000,IF(D31="nâng cao",250000,IF(D31="toàn diện",400000,IF(D31="Hoàn hảo",600000,0)))) -> 250000 | E36: =IF(E31="cơ bản",150000,IF(E31="nâng cao",250000,IF(E31="toàn diện",400000,IF(E31="Hoàn hảo",600000,0)))) -> 0 | F36: =IF(F31="cơ bản",150000,IF(F31="nâng cao",250000,IF(F31="toàn diện",400000,IF(F31="Hoàn hảo",600000,0)))) -> 0 | G36: =IF(G31="cơ bản",150000,IF(G31="nâng cao",250000,IF(G31="toàn diện",400000,IF(G31="Hoàn hảo",600000,0)))) -> 0
B37: Phẫu thuật (tối đa 30 ngày trước khi nhập viện; 02 lần khám/Đợt điều trị) | D37: =IF(D31=0,0,VLOOKUP('Tinh phi QL'!$G$17,The!$A$6:$R$9,6,0)) -> Chi phí thực tế | E37: =IF(E31=0,0,VLOOKUP('Tinh phi QL'!$G$36,The!$A$6:$R$9,6,0)) -> 0 | F37: =IF(F31=0,0,VLOOKUP('Tinh phi QL'!$G$56,The!$A$6:$R$9,6,0)) -> 0 | G37: =IF(G31=0,0,VLOOKUP('Tinh phi QL'!$G$75,The!$A$6:$R$9,6,0)) -> 0
B38: Điều trị trước khi nhập viện (tối đa 60 ngày sau khi xuất viện) | D38: =IF(D31=0,0,VLOOKUP('Tinh phi QL'!$G$17,The!$A$6:$R$9,7,0)) -> Chi phí thực tế | E38: =IF(E31=0,0,VLOOKUP('Tinh phi QL'!$G$36,The!$A$6:$R$9,7,0)) -> 0 | F38: =IF(F31=0,0,VLOOKUP('Tinh phi QL'!$G$56,The!$A$6:$R$9,7,0)) -> 0 | G38: =IF(G31=0,0,VLOOKUP('Tinh phi QL'!$G$75,The!$A$6:$R$9,7,0)) -> 0
B39: Điều trị sau khi nhập viện | D39: =IF(D31=0,0,VLOOKUP('Tinh phi QL'!$G$17,The!$A$6:$R$9,8,0)) -> Chi phí thực tế | E39: =IF(E31=0,0,VLOOKUP('Tinh phi QL'!$G$36,The!$A$6:$R$9,8,0)) -> 0 | F39: =IF(F31=0,0,VLOOKUP('Tinh phi QL'!$G$56,The!$A$6:$R$9,8,0)) -> 0 | G39: =IF(G31=0,0,VLOOKUP('Tinh phi QL'!$G$75,The!$A$6:$R$9,8,0)) -> 0
B40: Chi phí y tế nội trú khác | D40: =IF(D31=0,0,VLOOKUP('Tinh phi QL'!$G$17,The!$A$6:$R$9,9,0)) -> Chi phí thực tế | E40: =IF(E31=0,0,VLOOKUP('Tinh phi QL'!$G$36,The!$A$6:$R$9,9,0)) -> 0 | F40: =IF(F31=0,0,VLOOKUP('Tinh phi QL'!$G$56,The!$A$6:$R$9,9,0)) -> 0 | G40: =IF(G31=0,0,VLOOKUP('Tinh phi QL'!$G$75,The!$A$6:$R$9,9,0)) -> 0
...

Sheet Than so hoc
A3: BÁO CÁO THẦN SỐ HỌC
A5: Dựa theo cuốn sách: Thần Số Học Ứng Dụng_Joy Woodward
A7: Ngày lập báo cáo: | H7: =TODAY() -> 46229
A9: Họ và tên: | D9: =CHUNG!K4 -> TRAN | E9: =CHUNG!R4 -> VAN | F9: =CHUNG!Y4 -> HUY | G9: =CHUNG!AF4 | H9: =CHUNG!AM4 | I9: =CHUNG!AT4
A10: Ngày tháng năm sinh: | D10: =CHUNG!C4 -> 15 | E10: =CHUNG!E4 -> 8 | F10: =CHUNG!H4 -> 1995
A12: THẦN SỐ HỌC LÀ GÌ?
A14: Thần số, thần số học hay còn gọi là số bí thuật là niềm tin ngụy khoa học vào mối quan hệ tín ngưỡng thần thánh và thần bí giữa các chữ số và sự kiện. Tư tưởng này cũng điều tra về sự tương quan giữa số của các chữ cái trong danh xưng với những thứ mang tính tinh thần. Tư tưởng này thông thường liên quan với siêu linh, cùng với thuật chiêm tinh và các nghệ thuật bói toán tương tự khác. Hệ thống Pythagoras Phương pháp này có thể được gọi là phương pháp thần số học phương Tây hoặc phương pháp thần số học Pitago. Pythagoras, nhà toán học và triết học người Hy Lạp sống từ năm 569–470 trước Công nguyên, được biết đến như là cha đẻ của môn số học phương Tây. Pythagoras bắt đầu lý thuyết về các con số của mình bằng cách khám phá ra mối quan hệ giữa các con số và các nốt nhạc. Ông phát hiện ra rằng dao động trong các nhạc cụ dây có thể được giải thích bằng toán học. Phương pháp Pythagore sử dụng tên và ngày sinh của một cá nhân. Số tên tiết lộ bản chất bên ngoài của cá nhân. Đây là tính cách mà họ thể hiện với thế giới bên ngoài. Để bắt đầu, bạn cần sử dụng tên đầy đủ của cá nhân như được ghi trên giấy khai sinh của họ. Sau đó, mỗi chữ cái được gán cho một số từ 1 đến 9, dựa trên hệ thống Pitago cổ đại. Các số được gán cho các chữ cái trong bảng chữ cái Latinh như sau: 1 = A,J,S 2 = B,K,T 3 = C,L,U 4 = D,M,V 5 = E,N,W 6 = F,O,X 7 = G,P,Y 8 = H,Q,Z 9 = I,R. Tiếp theo, cộng tất cả các số được liên kết với mỗi chữ cái trong tên khai sinh đầy đủ của bạn. Sau đó, con số được giảm đi cho đến khi bạn nhận được một chữ số.
A17: (Nguồn: Wikipedia)
A21: BẢNG TỔNG HỢP TỔNG QUAN
A23: Họ và tên: | D23: =D9 -> TRAN | E23: =E9 -> VAN | F23: =F9 -> HUY | G23: =G9 | H23: =H9 | I23: =I9
A24: Ngày tháng năm sinh: | D24: =D10 -> 15 | E24: =E10 -> 8 | F24: =F10 -> 1995
G25: =CHUNG!H4+G36 -> 2029 | I25: =IF(I26=11,11,IF(I26=22,4,IF(I26=33,6,IF(I26<10,I26,0)))) -> 2
A26: CON SỐ ĐƯỜNG ĐỜI | I26: =CHUNG!B12 -> 2
A27: CON SỐ VẬN MỆNH | I27: =CHUNG!K12 -> 9
A28: CON SỐ LINH HỒN | I28: =CHUNG!BB12 -> 5
A29: CON SỐ TÍNH CÁCH | I29: =CHUNG!CS12 -> 4
A30: CON SỐ NGÀY SINH | I30: =CHUNG!H17 -> 6
A31: CON SỐ THÁI ĐỘ | I31: =CHUNG!AL17 -> 5
A32: CON SỐ TRƯỞNG THÀNH | I32: =CHUNG!H22 -> 11
A33: NĂM CÁ NHÂN | I33: =CHUNG!AL22 -> 6
A34: THÁNG CÁ NHÂN | I34: =CHUNG!CA22 -> 4
A35: NĂM ĐỈNH CAO THÀNH CÔNG | F35: Đỉnh | G35: Tuổi | I35: Năm
F36: Đỉnh 1 | G36: =36-I25 -> 34 | I36: =G25 -> 2029
F37: Đỉnh 2 | G37: =G36+9 -> 43 | I37: =I36+9 -> 2038
F38: Đỉnh 3 | G38: =G37+9 -> 52 | I38: =I37+9 -> 2047
F39: Đỉnh 4 | G39: =G38+9 -> 61 | I39: =I38+9 -> 2056
A43: GIẢI NGHĨA CHI TIẾT
A45: Con số đường đời
A47: Tiết lộ con đường dặc biệt mà bạn sẽ định hướng trong cuộc đời, đường đời là con số quan trọng nhất trong hồ sơ cốt lõi, khám phá tài năng thiên bẩm, tính cách, cơ hội, bài học quan trọng.
A49: Số: | B49: =CHUNG!B12 -> 2 | D49: Ý nghĩa: | E49: =CHUNG!B13 -> TỐT BỤNG, NGOẠI GIAO TỐT
A51: =VLOOKUP('ĐƯỜNG ĐỜI'!D2,'ĐƯỜNG ĐỜI'!B2:P14,3,0) -> Tốt bụng, ngoại giao tốt và có tinh thần hợp tác đều là những đặc điểm nổi bật của con số đường đời 2. Bạn là người kiên nhẫn nhất trong tất cả các con số và cực kỳ nhạy cảm, nhạy bén và giàu cảm xúc. Cảm xúc của bạn có thể chuyển từ khóc sang cười. Cùng với sự nhạy cảm đó là những khả năng về trực giác, bạn có khả năng bẩm sinh để cảm nhận cảm xúc của người khác. Tuy nhiên bạn phải chắc chắn không hy sinh ý kiến và cảm xúc cá nhân hoặc thỏa hiệp chỉ để giữ hòa khí, vì điều này có thể tạo ra sự oán giận. Khi nói đến các mối quan hệ, bản chất kiên nhẫn, thích thỏa hiệp của bạn có thể thu hút những người cố chấp thay vì một người bạn đời phù hợp và chín chắn. Bạn khó có thể sống độc thân lâu và có thể trải qua nhiều mối tình, chuyển từ người này sang người khác. Bạn cảm thấy thoải mái khi có đôi có cặp hơn là sống một mình. Bạn là một nhà đàm phán và hòa giải bẩm sinh. Không phải lúc nào bạn cũng nhận được sự tín nhiệm hoặc công nhận mà bạn xứng đáng. Bạn có thể quan tâm quá mức đến những gì người khác nghĩ. Bạn sẽ thành công trong nghề nghiệp cho phép bạn giúp đỡ người khác, các lĩnh vực như hòa giải, giảng dạy hoặc tư vấn. Con số đường đời 2 cũng là những người có khiếu thẩm mỹ đặc biệt. Họ có thể áp dụng kỹ năng này vào công việc thiết kế hoặc các hoạt động nghệ thuật. Họ cũng có thể thể hiện kỹ năng đàm phán mạnh mẽ và thể hiện sự thông minh trong lĩnh vực chính trị hoặc luật pháp. Mức độ nhạy cảm của con số đường đời này mở rộng đối với tất cả các loại chất gây dị ứng, bao gồm thực phẩm, sản phẩm chăm sóc da và tóc, bụi, hóa chất, dược phẩm và nhiều loại khác. Các vấn đề sức khỏe khác có thể gồm lo lắng thái quá, trầm cảm và các vấn đề về dạ dày. Số 2 có dáng cong và cho thấy sự thỏa hiệp, vì vậy bạn cần phải học cách đứng lên bảo vệ chính mình.
A67: Con số vận mệnh
A68: Tiết lộ khả năng tinh thần và thể chất, thể hiện mục tiêu, mẫu người bạn muốn trở thành.
A69: Số: | B69: =CHUNG!K12 -> 9 | D69: Ý nghĩa: | E69: =CHUNG!K13 -> NGƯỜI CÓ TẤM LÒNG NHÂN ĐẠO
A71: =VLOOKUP('VẬN MỆNH'!D2,'VẬN MỆNH'!B2:P14,3,0) -> Bạn có thể thu phục hầu hết mọi người bằng khiếu hài hước; tính cách hướng ngoại & sự quyến rũ của mình. Bạn là người có tầm nhìn xa và có thể truyền cảm hứng cho những người khác tham gia vào một phong trào giúp thế giới trở nên tốt đẹp hơn. Bạn có thể lý tưởng hóa mọi thứ và thậm chí ngây thơ về động cơ của người khác. Bạn là người dễ gây ấn tượng và dễ hình thành thói quen, có thể bao gồm lạm dụng chất kích thích. Bạn là người kiên nhẫn, nhân ái & lãng mạn. Bạn muốn được thế giới công nhận & bí mật tìm kiếm sự nổi tiếng. Chia sẻ tài năng của mình, giúp đỡ nhân loại, dạy dỗ, tư vấn & chữa lành cho mọi người là những điều nuôi dưỡng tâm hồn bạn. Trong khi theo đuổi mong muốn giải cứu thế giới, hãy đảm bảo bạn không bỏ bê những người thân thiết của mình. Mặt tối tính cách của bạn có thể là tính chiếm hữu, ủ rũ, nhút nhát, ngây thơ & dễ bồn chồn. Là người nghiện mua sắm, bạn rất dễ phung phí tiền bạc.
A93: Con số linh hồn
A94: Quy định các quyết định do trái tim đưa ra, nơi chứa đựng ước mơ, mong muốn, khao khát.
A95: Số: | B95: =CHUNG!BB12 -> 5 | D95: Ý nghĩa: | E95: =CHUNG!BB13 -> NGƯỜI CÓ TÂM HỒN TỰ DO
A97: =VLOOKUP('LINH HỒN'!D2,'LINH HỒN'!B2:P14,3,0) -> Tự do là yếu tố cần thiết cho hạnh phúc của con số linh hồn 5. Với niềm đam mê sâu sắc đối với sự thay đổi, du lịch và phiêu lưu, bạn tìm kiếm cảm giác không bị gò bó, giới hạn trong các mối quan hệ. Nhóm này khó giữ lời hứa và cũng không tuân thủ tốt các yêu cầu mệnh lệnh. Số 5 thường bị chi phối bởi các giác quan nên quan hệ tình dục là điều đặc biệt quan trọng với nhóm này. Bạn luôn muốn sự đa dạng và điều đó mở rộng đến cả phòng ngủ. Những thú vui cảm xúc mang đến cho bạn niềm hạnh phúc nhưng cũng có thể dẫn đến sự vô độ và lạm dụng. Con số linh hồn 5 thường có xu hướng kết hôn muộn hơn. Họ chống lại những ràng buộc tình cảm và những cam kết lâu dài.
A114: Con số tính cách
...

Sheet VTLGTTKcamket
B2: Vững Tương Lai | H2: Quyền lợi minh họa tại mức lãi suất cam kết
B4: CHÚ Ý KIỂM TRA LẠI PHẦN TÍNH PHÍ XEM ĐÚNG TUỔI, GIỚI TÍNH, QUYỀN LỢI! | M4: Đơn vị: 000 đ
B5: Năm HĐ | C5: Năm đóng phí | D5: Tuổi | E5: Tổng phí bảo hiểm sản phẩm BHNT | F5: Phí sản phẩm BHNT đem đi đầu tư | G5: Phí bảo hiểm sản phẩm BHBK | H5: Quyền lợi tử vong/ TTTBVV
H6: Quyền lợi TTTB&VV (trước 75 tuổi)/ Tử vong | I6: Thưởng duy trì đóng phí | J6: GTTK cơ bản | K6: GTTK đóng thêm | L6: GTTK hợp đồng | M6: Giá trị hoàn lại của hợp đồng
B7: 1 | C7: =IF(ROW(A1)>'Tinh phi QL'!$D$13,"",ROW(A1)) -> 1 | D7: ='Tinh phi QL'!I8 -> 30 | E7: =IF(IFERROR(--TRIM(C7),0)=0,0,'Tinh phi QL'!$H$13/1000) -> 10000 | F7: =E7*50% -> 5000 | G7: =KTVBVPhi20nam!AI4 -> 6571 | H7: =MAX('Tinh phi QL'!$E$13/1000,J7)+K7 -> 1000000 | J7: =IF(VLOOKUP(B7,VTL20namcamket!$B$4:$M$243,10,0)<=0,"Mất hiệu lực",VLOOKUP(B7,VTL20namcamket!$B$4:$M$243,10,0)) -> 3265.5581 | L7: =J7 -> 3265.5581 | M7: =IF(L7-100%*E7>0,L7-100%*E7,0) -> 0
B8: 2 | C8: =IF(ROW(A2)>'Tinh phi QL'!$D$13,"",ROW(A2)) -> 2 | D8: =D7+1 -> 31 | E8: =IF(IFERROR(--TRIM(C8),0)=0,0,'Tinh phi QL'!$H$13/1000) -> 10000 | F8: =E8*70% -> 7000 | G8: =KTVBVPhi20nam!AI5 -> 6571 | H8: =MAX('Tinh phi QL'!$E$13/1000,J8)+K8 -> 1000000 | J8: =IF(VLOOKUP(B8,VTL20namcamket!$B$4:$M$243,10,0)<=0,"Mất hiệu lực",VLOOKUP(B8,VTL20namcamket!$B$4:$M$243,10,0)) -> 8636.4066 | L8: =J8 -> 8636.4066 | M8: =IF(L8-100%*E8>0,L8-100%*E8,0) -> 0
B9: 3 | C9: =IF(ROW(A3)>'Tinh phi QL'!$D$13,"",ROW(A3)) -> 3 | D9: =D8+1 -> 32 | E9: =IF(IFERROR(--TRIM(C9),0)=0,0,'Tinh phi QL'!$H$13/1000) -> 10000 | F9: =E9*80% -> 8000 | G9: =KTVBVPhi20nam!AI6 -> 6571 | H9: =MAX('Tinh phi QL'!$E$13/1000,J9)+K9 -> 1000000 | J9: =IF(VLOOKUP(B9,VTL20namcamket!$B$4:$M$243,10,0)<=0,"Mất hiệu lực",VLOOKUP(B9,VTL20namcamket!$B$4:$M$243,10,0)) -> 15151.801 | L9: =J9 -> 15151.801 | M9: =L9-45%*E9 -> 10651.801
B10: 4 | C10: =IF(ROW(A4)>'Tinh phi QL'!$D$13,"",ROW(A4)) -> 4 | D10: =D9+1 -> 33 | E10: =IF(IFERROR(--TRIM(C10),0)=0,0,'Tinh phi QL'!$H$13/1000) -> 10000 | F10: =E10*80% -> 8000 | G10: =KTVBVPhi20nam!AI7 -> 6571 | H10: =MAX('Tinh phi QL'!$E$13/1000,J10)+K10 -> 1000000 | J10: =IF(VLOOKUP(B10,VTL20namcamket!$B$4:$M$243,10,0)<=0,"Mất hiệu lực",VLOOKUP(B10,VTL20namcamket!$B$4:$M$243,10,0)) -> 21527.822 | L10: =J10 -> 21527.822 | M10: =L10-30%*E10 -> 18527.822
B11: 5 | C11: =IF(ROW(A5)>'Tinh phi QL'!$D$13,"",ROW(A5)) -> 5 | D11: =D10+1 -> 34 | E11: =IF(IFERROR(--TRIM(C11),0)=0,0,'Tinh phi QL'!$H$13/1000) -> 10000 | F11: =E11*80% -> 8000 | G11: =KTVBVPhi20nam!AI8 -> 6571 | H11: =MAX('Tinh phi QL'!$E$13/1000,J11)+K11 -> 1000000 | I11: =VLOOKUP(B11,VTL20namcamket!$B$4:$I$243,8,0) -> 300 | J11: =IF(VLOOKUP(B11,VTL20namcamket!$B$4:$M$243,10,0)<=0,"Mất hiệu lực",VLOOKUP(B11,VTL20namcamket!$B$4:$M$243,10,0)) -> 28201.908 | L11: =J11 -> 28201.908 | M11: =L11-20%*E11 -> 26201.908
B12: 6 | C12: =IF(ROW(A6)>'Tinh phi QL'!$D$13,"",ROW(A6)) -> 6 | D12: =D11+1 -> 35 | E12: =IF(IFERROR(--TRIM(C12),0)=0,0,'Tinh phi QL'!$H$13/1000) -> 10000 | F12: =E12*98% -> 9800 | G12: =KTVBVPhi20nam!AI9 -> 7495 | H12: =MAX('Tinh phi QL'!$E$13/1000,J12)+K12 -> 1000000 | I12: =VLOOKUP(B12,VTL20namcamket!$B$4:$I$243,8,0) -> 300 | J12: =IF(VLOOKUP(B12,VTL20namcamket!$B$4:$M$243,10,0)<=0,"Mất hiệu lực",VLOOKUP(B12,VTL20namcamket!$B$4:$M$243,10,0)) -> 36582.134 | L12: =J12 -> 36582.134 | M12: =L12-0%*E12 -> 36582.134
B13: 7 | C13: =IF(ROW(A7)>'Tinh phi QL'!$D$13,"",ROW(A7)) -> 7 | D13: =D12+1 -> 36 | E13: =IF(IFERROR(--TRIM(C13),0)=0,0,'Tinh phi QL'!$H$13/1000) -> 10000 | F13: =E13*98% -> 9800 | G13: =KTVBVPhi20nam!AI10 -> 7495 | H13: =MAX('Tinh phi QL'!$E$13/1000,J13)+K13 -> 1000000 | I13: =VLOOKUP(B13,VTL20namcamket!$B$4:$I$243,8,0) -> 300 | J13: =IF(VLOOKUP(B13,VTL20namcamket!$B$4:$M$243,10,0)<=0,"Mất hiệu lực",VLOOKUP(B13,VTL20namcamket!$B$4:$M$243,10,0)) -> 44987.294 | L13: =J13 -> 44987.294 | M13: =L13 -> 44987.294
B14: 8 | C14: =IF(ROW(A8)>'Tinh phi QL'!$D$13,"",ROW(A8)) -> 8 | D14: =D13+1 -> 37 | E14: =IF(IFERROR(--TRIM(C14),0)=0,0,'Tinh phi QL'!$H$13/1000) -> 10000 | F14: =E14*98% -> 9800 | G14: =KTVBVPhi20nam!AI11 -> 7495 | H14: =MAX('Tinh phi QL'!$E$13/1000,J14)+K14 -> 1000000 | I14: =VLOOKUP(B14,VTL20namcamket!$B$4:$I$243,8,0) -> 300 | J14: =IF(VLOOKUP(B14,VTL20namcamket!$B$4:$M$243,10,0)<=0,"Mất hiệu lực",VLOOKUP(B14,VTL20namcamket!$B$4:$M$243,10,0)) -> 53404.573 | L14: =J14 -> 53404.573 | M14: =L14 -> 53404.573
